Workbook

Sheet Dati generali
A1: Tipologia prospetto ripartizione spese | I1: C
A2: Vettori energetici:
A3: Vettore 1 | I3: gas naturale
A4: Vettore 2 | I4: energia elettrica
A5: Generatori | I5: generatore a combustione per climatizzazione invernale e ACS
A6: Tipologia di contabilizzazione dell'energia termica utile prodotta dal generatore | I6: contatore di calore
A7: Numero di unità immobiliare | I7: 10
A8: Numero di locali ad uso collettivo | I8: 0
A9: Tipologia di contabilizzazione dei consumi di energia termica utile delle unità immobiliari per climatizzazione invernale | I9: ripartitori
A10: Tipologia di contabilizzazione dei consumi di energia termica utile delle unità immobiliari per ACS | I10: contatori volumetrici
A11: Periodo considerato | I11: stagione annuale
A12: Criterio di ripartizione della spesa totale per potenza termica installata per climatizzazione invernale | H12: Sp,cli | I12: millesimi di fabbisogno di energia termica utile
A13: Spesa totale per conduzione e manutenzione ordinaria dell'impianto centralizzato | H13: Scm | I13: 1892 | J13: €
A14: Spesa totale per la gestione del servizio di contabilizzazione dell'energia termica utile | H14: Scr | I14: 1376.16 | J14: €
A15: Perdite dell'impianto di climatizzazione invernale nel periodo considerato | H15: Pcli | I15: 126203.13 | J15: kWh
A16: Fabbisogno annuo di energia termica dell'edificio utile per climatizzazione invernale | H16: Qh,cli | I16: 470907.21 | J16: kWh
A17: Fabbisogno annuo di enrgia termica utile dell'edificio per ACS | H17: Qh,acs | I17: 55741.77 | J17: kWh
A18: Fabbisogno ideale di energia termica utile dell'edificio per climatizzazione invernale nel periodo considerato | H18: Qh,id,cli | I18: 282661.63 | J18: kWh
A19: Frazione del fabbisogno ideale di energia termica utile dell'edificio per climatizzazione invernale da attribuire al consumo involontario (coefficiente ricavato dal prospetto 10 della UNI 10200) | H19: kinv
B22: Valori da inserire
B23: Valori da calcolo UNI

Sheet Vettori energetici
A1: Vettore 1 (combustibile)
A2: Lettura iniziale del contatore di combustibile | E2: L1,ct,1 | F2: 0 | G2: mc
A3: Lettura finale del contatore di combustibile | E3: L2,ct,1 | F3: 36124 | G3: mc
A4: Fabbisogno per climatizzazione invernale nel periodo considerato | E4: Q've,cli,1 | F4: 51094.779 | G4: kWh o mc | I4: Kcli = | J4: =F4/(F4+F5) -> 0.86493857
A5: Fabbisogno per ACS nel periodo considerato | E5: Q've,acs,1 | F5: 7978.525 | G5: kWh o mc | I5: kacs = | J5: =F5/(F4+F5) -> 0.13506143
A6: Costo unitario | E6: Cve,1 | F6: 0.9251 | G6: €/mc
A8: Vettore 2 (energia elettrica)
A9: Lettura iniziale del contatore di energia elettrica | E9: L1,ct,2 | F9: 0 | G9: kWh
A10: Lettura finale del contatore di energia elettrica | E10: L2,ct,2 | F10: 4750.76 | G10: kWh
A11: Fabbisogno per climatizzazione invernale nel periodo considerato | E11: Q've,cli,2 | F11: 4271.2 | G11: kWh | I11: Kcli = | J11: =F11/(F11+F12) -> 0.57709171
A12: Fabbisogno per ACS nel periodo considerato | E12: Q've,acs,2 | F12: 3130.05 | G12: kWh | I12: kacs = | J12: =F12/(F11+F12) -> 0.42290829
A13: Costo unitario | E13: Cve,2 | F13: 0.3046 | G13: €/kWh
B17: Valori da inserire
B18: Valori da calcolo UNI

Sheet Generatore
A2: Generatore riscaldamento
A3: Lettura iniziale del contatore di calore | E3: L1,cc | F3: 0 | G3: kWh
A4: Lettura finale del contatore di calore | E4: L2,cc | F4: ='Vettori energetici'!F3*9.45*0.987*N5 -> 247646.47 | G4: kWh
A5: Fabbisogno di energia termica utile applicato al generatore per climatizzazione invernale nel periodo considerato | E5: Q'gn,cli | F5: 470907.21 | G5: kWh | N5: 0.735
I7: totale fabbisogno Risc+Acs | M7: =F5+F11 -> 526648.98 | P7: =F4+F10 -> 336933.97
A8: Generatore ACS
A9: Lettura iniziale del contatore di calore | E9: L1,cc | F9: 0 | G9: kWh
A10: Lettura finale del contatore di calore | E10: L2,cc | F10: ='Vettori energetici'!F3*9.45*0.987*N11 -> 89287.501 | G10: kWh
A11: Fabbisogno di energia termica utile applicato al generatore per ACS nel periodo considerato | E11: Q'gn,acs | F11: 55741.77 | G11: kWh | N11: =1-N5 -> 0.265
B13: Valori da inserire
B14: Valori da calcolo UNI

Sheet Letture-mill. u.i.
A1: Unità immobiliare
A2: Unità immobiliare 1 - ALBERIZZI
A3: Lettura iniziale ripartitore - corpo scaldante 1 | E3: L1,r,1,1 | F3: 0 | G3: ur
A4: Lettura finale ripartitore - corpo scaldante 1 | E4: L2,r,1,1 | F4: 608 | G4: ur
A5: Lettura iniziale ripartitore - corpo scaldante 2 | E5: L1,r,2,1 | F5: 0 | G5: ur
A6: Lettura finale ripartitore - corpo scaldante 2 | E6: L2,r,2,1 | F6: 2016 | G6: ur
A7: Lettura iniziale ripartitore - corpo scaldante 3 | E7: L1,r,3,1 | F7: 0 | G7: ur
A8: Lettura finale ripartitore - corpo scaldante 3 | E8: L2,r,3,1 | F8: 1260 | G8: ur
A9: Lettura iniziale ripartitore - corpo scaldante 4 | E9: L1,r,4,1 | F9: 0 | G9: ur
A10: Lettura finale ripartitore - corpo scaldante 4 | E10: L2,r,4,1 | F10: 1512 | G10: ur
A11: Lettura iniziale ripartitore - corpo scaldante 5 | E11: L1,r,5,1 | F11: 0 | G11: ur
A12: Lettura finale ripartitore - corpo scaldante 5 | E12: L2,r,5,1 | F12: 1412 | G12: ur
A13: Lettura iniziale ripartitore - corpo scaldante 6 | E13: L1,r,6,1 | F13: 0 | G13: ur
A14: Lettura finale ripartitore - corpo scaldante 6 | E14: L2,r,6,1 | F14: 1412 | G14: ur
... A26: Lettura finale del contatore volumetrico | E26: L2,cv,1 | F26: 36 | G26: mc
A27: Millesimi di fabbisogno di energiatermica utile per climatizzazione invernale | E27: mQh,cli,1 | F27: 24.02
A28: Millesimi di fabbisogno di energiatermica utile per ACS | E28: mQh,acs,1 | F28: 25.78
A30: Unità immobiliare 2 - PISANI
A31: Lettura iniziale ripartitore - corpo scaldante 1 | E31: L1,r,1,2 | F31: 0 | G31: ur
A32: Lettura finale ripartitore - corpo scaldante 1 | E32: L2,r,1,2 | F32: 362 | G32: ur
A33: Lettura iniziale ripartitore - corpo scaldante 2 | E33: L1,r,2,2 | F33: 0 | G33: ur
A34: Lettura finale ripartitore - corpo scaldante 2 | E34: L2,r,2,2 | F34: 486 | G34: ur
A35: Lettura iniziale ripartitore - corpo scaldante 3 | E35: L1,r,3,2 | F35: 0 | G35: ur
A36: Lettura finale ripartitore - corpo scaldante 3 | E36: L2,r,3,2 | F36: 313 | G36: ur
A37: Lettura iniziale ripartitore - corpo scaldante 4 | E37: L1,r,4,2 | F37: 0 | G37: ur
A38: Lettura finale ripartitore - corpo scaldante 4 | E38: L2,r,4,2 | F38: 233 | G38: ur
A39: Lettura iniziale ripartitore - corpo scaldante 5 | E39: L1,r,5,2 | F39: 0 | G39: ur
A40: Lettura finale ripartitore - corpo scaldante 5 | E40: L2,r,5,2 | F40: 363 | G40: ur
A41: Lettura iniziale ripartitore - corpo scaldante 6 | E41: L1,r,6,2 | F41: 0 | G41: ur
A42: Lettura finale ripartitore - corpo scaldante 6 | E42: L2,r,6,2 | F42: 147 | G42: ur
... A46: Lettura finale del contatore volumetrico | E46: L2,cv,2 | F46: 23 | G46: mc
A47: Millesimi di fabbisogno di energiatermica utile per climatizzazione invernale | E47: mQh,cli,2 | F47: 16.67
A48: Millesimi di fabbisogno di energiatermica utile per ACS | E48: mQh,acs,2 | F48: 21.4
A50: Unità immobiliare 3 - APONE
A51: Lettura iniziale ripartitore - corpo scaldante 1 | E51: L1,r,1,3 | F51: 0 | G51: ur
A52: Lettura finale ripartitore - corpo scaldante 1 | E52: L2,r,1,3 | F52: 837 | G52: ur
A53: Lettura iniziale ripartitore - corpo scaldante 2 | E53: L1,r,2,3 | F53: 0 | G53: ur
A54: Lettura finale ripartitore - corpo scaldante 2 | E54: L2,r,2,3 | F54: 937 | G54: ur
A55: Lettura iniziale ripartitore - corpo scaldante 3 | E55: L1,r,3,3 | F55: 0 | G55: ur
A56: Lettura finale ripartitore - corpo scaldante 3 | E56: L2,r,3,3 | F56: 357 | G56: ur
...

Sheet Consumi vet energ.
A2: Vettore 1 (combustibile)
A3: Calcolo del coefficiente di ripartizione per Riscaldamento | E3: kcli,1 | F3: ='Vettori energetici'!J4 -> 0.86493857
A4: Calcolo del coefficiente di ripartizione per ACS | E4: kacs,1 | F4: ='Vettori energetici'!J5 -> 0.13506143
A5: Calcolo del consumo per Riscaldamento | E5: Qve,cli,1 | F5: =('Vettori energetici'!F3-'Vettori energetici'!F2)*F3 -> 31245.041 | G5: mc
A6: Calcolo del consumo per ACS | E6: Qve,acs,1 | F6: =('Vettori energetici'!F3-'Vettori energetici'!F2)*F4 -> 4878.9592 | G6: mc
F7: =SUM(F5:F6) -> 36124
A8: Vettore 2 (energia elettrica)
A9: Calcolo del coefficiente di ripartizione per Riscaldamento | E9: kcli,2 | F9: ='Vettori energetici'!J11 -> 0.57709171
A10: Calcolo del coefficiente di ripartizione per ACS | E10: kacs,2 | F10: ='Vettori energetici'!J12 -> 0.42290829
A11: Calcolo del consumo per Riscaldamento | E11: Qve,cli,2 | F11: =('Vettori energetici'!F10-'Vettori energetici'!F9)*F9 -> 2741.6242 | G11: kWh
A12: Calcolo del consumo per ACS | E12: Qve,acs,2 | F12: =('Vettori energetici'!F10-'Vettori energetici'!F9)*F10 -> 2009.1358 | G12: kWh
F13: =F11+F12 -> 4750.76
A14: Calcolo dei contributi di energia termica utile del generatore
A15: Calcolo del contributo di energia termica utile per Riscaldamento | E15: Qgn,cli | F15: =IF('Dati generali'!I1="C",(Generatore!F4-Generatore!F3),IF('Dati generali'!I1="P",Generatore!F5,"ERRORE")) -> 247646.47 | G15: kWh
A16: Calcolo del contributo di energia termica utile per ACS | E16: Qgn,acs | F16: =IF('Dati generali'!I1="C", (Generatore!F10-Generatore!F9),IF('Dati generali'!I1="P",Generatore!F11,"ERRORE")) -> 89287.501 | G16: kWh
A18: Calcolo del consumo totale di energia termica utile dell'edificio per Riscaldamento e ACS
A19: Calcolo del consumo totale di energia termica utile dell'edificio per Riscaldamento | E19: Qcli | F19: =F15 -> 247646.47 | G19: kWh
A20: Calcolo del consumo totale di energia termica utile dell'edificio per ACS | E20: Qacs | F20: =F16 -> 89287.501 | G20: kWh
A21: Calcolo del consumo totale di energia termica utile dell'edificio per Riscaldamento e ACS | E21: Qt | F21: =F19+F20 -> 336933.97 | G21: kWh
B25: Valori da inserire
B26: Valori da calcolo UNI

Sheet Spese e costi unitari
A2: Calcolo della spesa totale per Riscaldamento e ACS
A3: Calcolo della spesa energetica per Riscaldamento | E3: Se,cli | F3: =('Vettori energetici'!F6*'Consumi vet energ.'!F5)+('Vettori energetici'!F13*'Consumi vet energ.'!F11) -> 29739.886 | G3: €
A4: Calcolo della spesa energetica per ACS | E4: Se,acs | F4: =('Vettori energetici'!F6*'Consumi vet energ.'!F6)+('Vettori energetici'!F13*'Consumi vet energ.'!F12) -> 5125.5079 | G4: €
A5: Calcolo del coefficiente di ripartizione per Riscaldamento | E5: kcli | F5: =Generatore!N5 -> 0.735
A6: Calcolo del coefficiente di ripartizione per ACS | E6: kacs | F6: =Generatore!N11 -> 0.265
A7: Calcolo della spesa per conduzione e manutenzione ordinaria dell'impianto termico centralizzato per Riscaldamento | E7: Scm,cli | F7: ='Dati generali'!I13*F5 -> 1390.62 | G7: €
A8: Calcolo della spesa per conduzione e manutenzione ordinaria dell'impianto termico centralizzato per ACS | E8: Scm,acs | F8: ='Dati generali'!I13*F6 -> 501.38 | G8: €
A9: Calcolo della spesa per la gestione del servizio di contabilizzazione dell'energia termica utile per Riscaldamento | E9: Scr,cli | F9: ='Dati generali'!I14*F5 -> 1011.4776 | G9: €
A10: Calcolo della spesa per la gestione del servizio di contabilizzazione dell'energia termica utile per ACS | E10: Scr,acs | F10: ='Dati generali'!I14*F6 -> 364.6824 | G10: €
A11: Calcolo della spesa totale per Riscaldamento | E11: Scli | F11: =F3+F7+F9 -> 32141.984 | G11: €
A12: Calcolo della spesa totale per ACS | E12: Sacs | F12: =F4+F8+F10 -> 5991.5703 | G12: €
A13: Calcolo della spesa totale per Riscaldamento e ACS | E13: St | F13: =F11+F12 -> 38133.554 | G13: €
A15: Calcolo dei costi unitari dell'energia termica utile
A16: Calcolo del costo unitario dell'energia termica utile per Riscaldamento | E16: ccli | F16: =F3/'Consumi vet energ.'!F19 -> 0.12009009 | G16: €/kWh
A17: Calcolo del costo unitario dell'energia termica utile per ACS | E17: cacs | F17: =F4/'Consumi vet energ.'!F20 -> 0.057404539 | G17: €/kWh
A19: Calcolo del consumo involontario di energia termica utile per Riscaldamento
A20: Calcolo del consumo involontario | E20: Qinv,cli | F20: ='Dati generali'!I15 -> 126203.13 | G20: kWh
B24: Valori da inserire
B25: Valori da calcolo UNI

Sheet Ripart. u.i.
A2: Calcolo delle unità di ripartizione delle singole unità immobiliari
A3: Unità immobiliare 1 | L3: RISC | M3: ACS | N3: Mill Clima | O3: Mill ACS
A4: Calcolo delle unità di ripartizione del corpo scaldante 1 | E4: urcs,1,1 | F4: ='Letture-mill. u.i.'!F4-'Letture-mill. u.i.'!F3 -> 608 | G4: ur | J4: 1 | K4: ALBERIZZI/PICCIRILLI | L4: 5168 | M4: 36 | N4: 24.02 | O4: 25.78
A5: Calcolo delle unità di ripartizione del corpo scaldante 2 | E5: urcs,2,1 | F5: ='Letture-mill. u.i.'!F6-'Letture-mill. u.i.'!F5 -> 2016 | G5: ur | J5: 2 | K5: ALBERIZZI/PISANI | L5: 9654 | M5: 23 | N5: 16.67 | O5: 21.4
A6: Calcolo delle unità di ripartizione del corpo scaldante 3 | E6: urcs,3,1 | F6: ='Letture-mill. u.i.'!F8-'Letture-mill. u.i.'!F7 -> 1260 | G6: ur | J6: 3 | K6: APONE GIULIO | L6: 3442 | M6: 30 | N6: 19.59 | O6: 21.32
A7: Calcolo delle unità di ripartizione del corpo scaldante 4 | E7: urcs,4,1 | F7: ='Letture-mill. u.i.'!F10-'Letture-mill. u.i.'!F9 -> 1512 | G7: ur | J7: 4 | K7: BADINI MARCO | L7: 4461 | M7: 57 | N7: 18.5 | O7: 21.37
A8: Calcolo delle unità di ripartizione del corpo scaldante 5 | E8: urcs,5,1 | F8: ='Letture-mill. u.i.'!F12-'Letture-mill. u.i.'!F11 -> 1412 | G8: ur | J8: 5 | K8: BARBIERI MARCO | L8: 6598 | M8: 49 | N8: 17.07 | O8: 21.4
A9: Calcolo delle unità di ripartizione del corpo scaldante 6 | E9: urcs,6,1 | F9: ='Letture-mill. u.i.'!F14-'Letture-mill. u.i.'!F13 -> 1412 | G9: ur | J9: 6 | K9: LANDI FRANCA | L9: 5259 | M9: 49 | N9: 23.17 | O9: 25.87
A10: Calcolo delle unità di ripartizione del corpo scaldante 7 | E10: urcs,7,1 | F10: ='Letture-mill. u.i.'!F16-'Letture-mill. u.i.'!F15 -> 1412 | G10: ur | J10: 7 | K10: BELLOMI VIVIANA | L10: 1040 | M10: 0 | N10: 20.31 | O10: 2.06
A11: Calcolo delle unità di ripartizione del corpo scaldante 8 | E11: urcs,8,1 | F11: ='Letture-mill. u.i.'!F18-'Letture-mill. u.i.'!F17 -> 1412 | G11: ur | J11: 8 | K11: BERTUCCA IVAN | L11: 3083 | M11: 41 | N11: 16.8 | O11: 21.31
A12: Calcolo delle unità di ripartizione del corpo scaldante 9 | E12: urcs,9,1 | F12: ='Letture-mill. u.i.'!F20-'Letture-mill. u.i.'!F19 -> 1412 | G12: ur | J12: 9 | K12: BLEJUT STEFAN | L12: 6837 | M12: 56 | N12: 28.87 | O12: 25.22
A13: Calcolo delle unità di ripartizione del corpo scaldante 10 | E13: urcs,10,1 | F13: ='Letture-mill. u.i.'!F22-'Letture-mill. u.i.'!F21 -> 1412 | G13: ur | J13: 10 | K13: BOLLANI ANGELINA | L13: 11634 | M13: 13 | N13: 20.38 | O13: 25.6
A14: Calcolo delle unità di ripartizione del corpo scaldante 11 | E14: urcs,11,1 | F14: ='Letture-mill. u.i.'!F24-'Letture-mill. u.i.'!F23 -> 1412 | G14: ur | J14: 11 | K14: CARENZIO ADRIANO | L14: 26931 | M14: 74 | N14: 16.96 | O14: 21.34
A15: Calcolo delle unità di ripartizione dell'unità immobiliare | E15: ur1 | F15: =SUM(F4:F14) -> 15280 | J15: 12 | K15: CASSE'/PEZZINI | L15: 3068 | M15: 27 | N15: 18.86 | O15: 25.83
J16: 13 | K16: CASSE' NATALIA | L16: 2162 | M16: 3 | N16: 22.27 | O16: 21.31
A17: Unità immobiliare 2 | J17: 14 | K17: RIZZI/CAVALLOTTI | L17: 17042 | M17: 96 | N17: 20.97 | O17: 25.57
A18: Calcolo delle unità di ripartizione del corpo scaldante 1 | E18: urcs,1,2 | F18: ='Letture-mill. u.i.'!F32-'Letture-mill. u.i.'!F31 -> 362 | G18: ur | J18: 15 | K18: CAJA EMILIO LUIGI | L18: 6932 | M18: 48 | N18: 21.4 | O18: 21.39
A19: Calcolo delle unità di ripartizione del corpo scaldante 2 | E19: urcs,2,2 | F19: ='Letture-mill. u.i.'!F34-'Letture-mill. u.i.'!F33 -> 486 | G19: ur | J19: 16 | K19: DE SANTOLO/CEVARZERE | L19: 12014 | M19: 68 | N19: 18.46 | O19: 21.56
A20: Calcolo delle unità di ripartizione del corpo scaldante 3 | E20: urcs,3,2 | F20: ='Letture-mill. u.i.'!F36-'Letture-mill. u.i.'!F35 -> 313 | G20: ur | J20: 17 | K20: CIVARDI MIRELLA | L20: 1059 | M20: 0 | N20: 20.91 | O20: 25.25
A21: Calcolo delle unità di ripartizione del corpo scaldante 4 | E21: urcs,4,2 | F21: ='Letture-mill. u.i.'!F38-'Letture-mill. u.i.'!F37 -> 233 | G21: ur | J21: 18 | K21: CRISTIANI SERGIO | L21: 3089 | M21: 10 | N21: 21.21 | O21: 21.39
A22: Calcolo delle unità di ripartizione del corpo scaldante 5 | E22: urcs,5,2 | F22: ='Letture-mill. u.i.'!F40-'Letture-mill. u.i.'!F39 -> 363 | G22: ur | J22: 19 | K22: D'ACUTO ANTONIO | L22: 7932 | M22: 53 | N22: 22.71 | O22: 25.26
A23: Calcolo delle unità di ripartizione del corpo scaldante 6 | E23: urcs,6,2 | F23: ='Letture-mill. u.i.'!F42-'Letture-mill. u.i.'!F41 -> 147 | G23: ur | J23: 20 | K23: DEL PRETE/STASI | L23: 5222 | M23: 0 | N23: 21.2 | O23: 2.04
A24: Calcolo delle unità di ripartizione del corpo scaldante 7 | E24: urcs,7,2 | F24: ='Letture-mill. u.i.'!F44-'Letture-mill. u.i.'!F43 -> 637 | G24: ur | J24: 21 | K24: FERRARI CLAUDIA | L24: 2989 | M24: 1 | N24: 17.26 | O24: 21.36
A25: Calcolo delle unità di ripartizione dell'unità immobiliare | E25: ur2 | F25: =SUM(F18:F24) -> 2541 | J25: 22 | K25: GALLI DONATELLA | L25: 2259 | M25: 2 | N25: 18.85 | O25: 21.56
J26: 23 | K26: MAGLIONA CATERINA | L26: 9335 | M26: 96 | N26: 19.04 | O26: 25.7
A27: Unità immobiliare 3 | J27: 24 | K27: MARCONI ANNA | L27: 5635 | M27: 11 | N27: 18.04 | O27: 21.72
A28: Calcolo delle unità di ripartizione del corpo scaldante 1 | E28: urcs,1,3 | F28: ='Letture-mill. u.i.'!F52-'Letture-mill. u.i.'!F51 -> 837 | G28: ur | J28: 25 | K28: FIORINO GIOVANNA | L28: 19805 | M28: 60 | N28: 18.96 | O28: 21.45
A29: Calcolo delle unità di ripartizione del corpo scaldante 2 | E29: urcs,2,3 | F29: ='Letture-mill. u.i.'!F54-'Letture-mill. u.i.'!F53 -> 937 | G29: ur | J29: 26 | K29: MORISETTI/FERRARI | L29: 8157 | M29: 19 | N29: 19.43 | O29: 25.32
A30: Calcolo delle unità di ripartizione del corpo scaldante 3 | E30: urcs,3,3 | F30: ='Letture-mill. u.i.'!F56-'Letture-mill. u.i.'!F55 -> 357 | G30: ur | J30: 27 | K30: NARATONE SANPIETRO | L30: 8254 | M30: 9 | N30: 19.97 | O30: 21.56
A31: Calcolo delle unità di ripartizione del corpo scaldante 4 | E31: urcs,4,3 | F31: ='Letture-mill. u.i.'!F58-'Letture-mill. u.i.'!F57 -> 332 | G31: ur | J31: 28 | K31: PAINELLI GIUSEPPE | L31: 6926 | M31: 80 | N31: 16.62 | O31: 21.45
A32: Calcolo delle unità di ripartizione del corpo scaldante 5 | E32: urcs,5,3 | F32: ='Letture-mill. u.i.'!F60-'Letture-mill. u.i.'!F59 -> 301 | G32: ur | J32: 29 | K32: PALADINI PIETRO | L32: 19007 | M32: 15 | N32: 23.22 | O32: 25.83
A33: Calcolo delle unità di ripartizione del corpo scaldante 6 | E33: urcs,6,3 | F33: ='Letture-mill. u.i.'!F62-'Letture-mill. u.i.'!F61 -> 58 | G33: ur | J33: 30 | K33: PANIGAZZI/LODOLA | L33: 4502 | M33: 6 | N33: 28.53 | O33: 23.43
A34: Calcolo delle unità di ripartizione del corpo scaldante 7 | E34: urcs,7,3 | F34: ='Letture-mill. u.i.'!F64-'Letture-mill. u.i.'!F63 -> 261 | G34: ur | J34: 31 | K34: PISOTTI FABRIZIO | L34: 16808 | M34: 102 | N34: 23.86 | O34: 22.09
A35: Calcolo delle unità di ripartizione del corpo scaldante 8 | E35: urcs,8,3 | F35: ='Letture-mill. u.i.'!F66-'Letture-mill. u.i.'!F65 -> 254 | G35: ur | J35: 32 | K35: RIBONI ALBERTO | L35: 2665 | M35: 0 | N35: 23.15 | O35: 20.68
A36: Calcolo delle unità di ripartizione dell'unità immobiliare | E36: ur3 | F36: =SUM(F28:F35) -> 3337 | J36: 33 | K36: ROSSANIGO/RIBONI | L36: 15116 | M36: 112 | N36: 29.88 | O36: 25.16
J37: 34 | K37: DE SANTOLO/ROVEDA | L37: 12749 | M37: 53 | N37: 17.48 | O37: 21.63
A38: Unità immobiliare 4 | J38: 35 | K38: SACCHI ORAZIO | L38: 15759 | M38: 21 | N38: 21.21 | O38: 25.29
A39: Calcolo delle unità di ripartizione del corpo scaldante 1 | E39: urcs,1,4 | F39: ='Letture-mill. u.i.'!F74-'Letture-mill. u.i.'!F73 -> 881 | G39: ur | J39: 36 | K39: SALERNO ROSELLA MARIA | L39: 1275 | M39: 29 | N39: 18.83 | O39: 26.05
A40: Calcolo delle unità di ripartizione del corpo scaldante 2 | E40: urcs,2,4 | F40: ='Letture-mill. u.i.'!F76-'Letture-mill. u.i.'!F75 -> 986 | G40: ur | J40: 37 | K40: SESTITO ANTONIO | L40: 8312 | M40: 47 | N40: 20.36 | O40: 25.29
A41: Calcolo delle unità di ripartizione del corpo scaldante 3 | E41: urcs,3,4 | F41: ='Letture-mill. u.i.'!F78-'Letture-mill. u.i.'!F77 -> 871 | G41: ur | J41: 38 | K41: SPAIRANI RICCARDO | L41: 5037 | M41: 37 | N41: 22.58 | O41: 21.21
...

Sheet Consumo e spesa
A1: Calcolo dei consumi di energia termica utile dellesingole unità immobiliari
A2: 1 | J2: Calcolo delle componenti del consumo totale di energia termica utile dell'edificio per Riscaldamento e ACS
A3: Calcolo dei consumi di energia termica utile per Riscaldamento | E3: Qui,cli,1 | F3: =('Consumi vet energ.'!$F$19-'Spese e costi unitari'!$F$20)*('Ripart. u.i.'!L4/'Ripart. u.i.'!$L$49) -> 1717.9043 | G3: kWh | J3: Calcolo delle componenti del consumo totale di energia termica utile dell'unità immobiliari per Riscaldamento | N3: Qui,cli,t
A4: Calcolo dei consumi di energia termica utile per ACS | E4: Qui,acs,1 | F4: =('Ripart. u.i.'!M4)*$K$26*$K$27*($K$28-$K$29) -> 1380.456 | G4: kWh | O4: =F3+F6+F9+F12+F15+F18+F21+F24+F27+F30+F33+F36+F39+F42+F45+F48+F51+F54+F57+F60+F63+F66+F69+F72+F75+F78+F81+F84+F87+F90+F93+F96+F99+F102+F105+F108+F111+F114+F117+F120+F123+F126+F129+F132+F135 -> 121443.34 | P4: kWh
A5: 2
A6: Calcolo dei consumi di energia termica utile per Riscaldamento | E6: Qui,cli,2 | F6: =('Consumi vet energ.'!$F$19-'Spese e costi unitari'!$F$20)*('Ripart. u.i.'!L5/'Ripart. u.i.'!$L$49) -> 3209.1037 | G6: kWh | J6: Calcolo delle componenti del consumo totale di energia termica utile dell'unità immobiliari per ACS | N6: Qui,acs,t
A7: Calcolo dei consumi di energia termica utile per ACS | E7: Qui,acs,2 | F7: =('Ripart. u.i.'!M5)*$K$26*$K$27*($K$28-$K$29) -> 881.958 | G7: kWh | O7: =F4+F7+F10+F13+F16+F19+F22+F25+F28+F31+F34+F37+F40+F43+F46+F49+F52+F55+F58+F61+F64+F67+F70+F73+F76+F79+F82+F85+F88+F91+F94+F97+F100+F103+F106+F109+F112+F115+F118+F121+F124+F127+F130+F133+F136 -> 63347.592 | P7: kWh
A8: 3
A9: Calcolo dei consumi di energia termica utile per Riscaldamento | E9: Qui,cli,3 | F9: =('Consumi vet energ.'!$F$19-'Spese e costi unitari'!$F$20)*('Ripart. u.i.'!L6/'Ripart. u.i.'!$L$49) -> 1144.1615 | G9: kWh | J9: Calcolo del consumo involontario di energia termica utile per ACS | N9: Qinv,acs
A10: Calcolo dei consumi di energia termica utile per ACS | E10: Qui,acs,3 | F10: =('Ripart. u.i.'!M6)*$K$26*$K$27*($K$28-$K$29) -> 1150.38 | G10: kWh | O10: ='Consumi vet energ.'!F20-O7 -> 25939.909 | P10: kWh
A11: 4
A12: Calcolo dei consumi di energia termica utile per Riscaldamento | E12: Qui,cli,4 | F12: =('Consumi vet energ.'!$F$19-'Spese e costi unitari'!$F$20)*('Ripart. u.i.'!L7/'Ripart. u.i.'!$L$49) -> 1482.8891 | G12: kWh
A13: Calcolo dei consumi di energia termica utile per ACS | E13: Qui,acs,4 | F13: =('Ripart. u.i.'!M7)*$K$26*$K$27*($K$28-$K$29) -> 2185.722 | G13: kWh | J13: Calcolo delle componenti della spesa totale per Riscaldamento e ACS
A14: 5 | J14: Calcolo delle componenti della spesa totale per il consumo di energia termica utile delle unità immobiliari per Riscaldamento | N14: Sui,cli
A15: Calcolo dei consumi di energia termica utile per Riscaldamento | E15: Qui,cli,5 | F15: =('Consumi vet energ.'!$F$19-'Spese e costi unitari'!$F$20)*('Ripart. u.i.'!L8/'Ripart. u.i.'!$L$49) -> 2193.2532 | G15: kWh | O15: ='Spese e costi unitari'!F16*O4 -> 14584.141 | P15: € | Q15: =SUM(O15,O21) -> 32141.984
A16: Calcolo dei consumi di energia termica utile per ACS | E16: Qui,acs,5 | F16: =('Ripart. u.i.'!M8)*$K$26*$K$27*($K$28-$K$29) -> 1878.954 | G16: kWh
A17: 6 | J17: Calcolo delle componenti della spesa totale per il consumo di energia termica utile delle unità immobiliari per ACS | N17: Sui,acs
A18: Calcolo dei consumi di energia termica utile per Riscaldamento | E18: Qui,cli,6 | F18: =('Consumi vet energ.'!$F$19-'Spese e costi unitari'!$F$20)*('Ripart. u.i.'!L9/'Ripart. u.i.'!$L$49) -> 1748.1538 | G18: kWh | O18: ='Spese e costi unitari'!F17*O7 -> 3636.4393 | P18: € | Q18: =SUM(O18,O23) -> 5991.5703
A19: Calcolo dei consumi di energia termica utile per ACS | E19: Qui,acs,6 | F19: =('Ripart. u.i.'!M9)*$K$26*$K$27*($K$28-$K$29) -> 1878.954 | G19: kWh
A20: 7 | J20: Calcolo della spesa totale per potenza termica installata per Riscaldamento | N20: Sp,cli
A21: Calcolo dei consumi di energia termica utile per Riscaldamento | E21: Qui,cli,7 | F21: =('Consumi vet energ.'!$F$19-'Spese e costi unitari'!$F$20)*('Ripart. u.i.'!L10/'Ripart. u.i.'!$L$49) -> 345.7083 | G21: kWh | O21: =('Spese e costi unitari'!F16*'Spese e costi unitari'!F20)+'Spese e costi unitari'!F7+'Spese e costi unitari'!F9 -> 17557.843 | P21: € | Q21: =SUM(Q15:Q19) -> 38133.554
A22: Calcolo dei consumi di energia termica utile per ACS | E22: Qui,acs,7 | F22: =('Ripart. u.i.'!M10)*$K$26*$K$27*($K$28-$K$29) -> 0 | G22: kWh | J22: Calcolo della spesa totale per potenza termica installata per ACS | N22: Sp,acs
A23: 8 | O23: =('Spese e costi unitari'!F17*O10)+'Spese e costi unitari'!F8+'Spese e costi unitari'!F10 -> 2355.1309 | P23: €
A24: Calcolo dei consumi di energia termica utile per Riscaldamento | E24: Qui,cli,8 | F24: =('Consumi vet energ.'!$F$19-'Spese e costi unitari'!$F$20)*('Ripart. u.i.'!L11/'Ripart. u.i.'!$L$49) -> 1024.8257 | G24: kWh
A25: Calcolo dei consumi di energia termica utile per ACS | E25: Qui,acs,8 | F25: =('Ripart. u.i.'!M11)*$K$26*$K$27*($K$28-$K$29) -> 1572.186 | G25: kWh
A26: 9 | J26: qp = | K26: 1000 | O26: =SUM(O15:O25) -> 38133.554
A27: Calcolo dei consumi di energia termica utile per Riscaldamento | E27: Qui,cli,9 | F27: =('Consumi vet energ.'!$F$19-'Spese e costi unitari'!$F$20)*('Ripart. u.i.'!L12/'Ripart. u.i.'!$L$49) -> 2272.6996 | G27: kWh | J27: mv = | K27: =1.162*10^-3 -> 0.001162
A28: Calcolo dei consumi di energia termica utile per ACS | E28: Qui,acs,9 | F28: =('Ripart. u.i.'!M12)*$K$26*$K$27*($K$28-$K$29) -> 2147.376 | G28: kWh | J28: θacs = | K28: 48
A29: 10 | J29: θf = | K29: 15
A30: Calcolo dei consumi di energia termica utile per Riscaldamento | E30: Qui,cli,10 | F30: =('Consumi vet energ.'!$F$19-'Spese e costi unitari'!$F$20)*('Ripart. u.i.'!L13/'Ripart. u.i.'!$L$49) -> 3867.2791 | G30: kWh
A31: Calcolo dei consumi di energia termica utile per ACS | E31: Qui,acs,10 | F31: =('Ripart. u.i.'!M13)*$K$26*$K$27*($K$28-$K$29) -> 498.498 | G31: kWh
A32: 11
A33: Calcolo dei consumi di energia termica utile per Riscaldamento | E33: Qui,cli,1 | F33: =('Consumi vet energ.'!$F$19-'Spese e costi unitari'!$F$20)*('Ripart. u.i.'!L14/'Ripart. u.i.'!$L$49) -> 8952.1828 | G33: kWh | R33: Valori da inserire
A34: Calcolo dei consumi di energia termica utile per ACS | E34: Qui,acs,1 | F34: =('Ripart. u.i.'!M14)*$K$26*$K$27*($K$28-$K$29) -> 2837.604 | G34: kWh | R34: Valori da calcolo UNI
A35: 12
A36: Calcolo dei consumi di energia termica utile per Riscaldamento | E36: Qui,cli,2 | F36: =('Consumi vet energ.'!$F$19-'Spese e costi unitari'!$F$20)*('Ripart. u.i.'!L15/'Ripart. u.i.'!$L$49) -> 1019.8395 | G36: kWh
A37: Calcolo dei consumi di energia termica utile per ACS | E37: Qui,acs,2 | F37: =('Ripart. u.i.'!M15)*$K$26*$K$27*($K$28-$K$29) -> 1035.342 | G37: kWh
A38: 13
A39: Calcolo dei consumi di energia termica utile per Riscaldamento | E39: Qui,cli,3 | F39: =('Consumi vet energ.'!$F$19-'Spese e costi unitari'!$F$20)*('Ripart. u.i.'!L16/'Ripart. u.i.'!$L$49) -> 718.67436 | G39: kWh
A40: Calcolo dei consumi di energia termica utile per ACS | E40: Qui,acs,3 | F40: =('Ripart. u.i.'!M16)*$K$26*$K$27*($K$28-$K$29) -> 115.038 | G40: kWh
...

Sheet Spese u.i.
A1: Calcolo delle spese delle singole unità immobiliari
A2: Unità 1
A3: Calcolo della spesa per il consumo di energia termica utile per riscaldamento | E3: Sui,cli,1 | F3: ='Spese e costi unitari'!$F$16*'Consumo e spesa'!F3 -> 206.30328 | G3: €
A4: Calcolo della spesa per il consumo di energia termica utile per ACS | E4: Sui,acs,1 | F4: ='Spese e costi unitari'!$F$17*'Consumo e spesa'!F4 -> 79.244441 | G4: €
A5: Calcolo della spesa per potenza termica installata per Riscaldamento | E5: Sp,cli,1 | F5: ='Consumo e spesa'!$O$21*('Letture-mill. u.i.'!F27/1000) -> 421.73938 | G5: €
A6: Calcolo della spesa per potenza termica installata per ACS | E6: Sp,acs,1 | F6: ='Consumo e spesa'!$O$23*('Letture-mill. u.i.'!F28/1000) -> 60.715276 | G6: €
A7: Calcolo della spesa totale per Riscaldamento | E7: Scli,1 | F7: =F3+F5 -> 628.04266 | G7: € | I7: =('Spese e costi unitari'!$F$16*'Consumo e spesa'!F3)+('Consumo e spesa'!$O$21*('Ripart. u.i.'!N4/1000)) -> 628.04266 | K7: =SUM(F9,F18,F27,F36,F45,F54,F63,F72,F81,F90) -> 7165.4062
A8: Calcolo della spesa totale per ACS | E8: Sacs,1 | F8: =F4+F6 -> 139.95972 | G8: € | I8: =('Spese e costi unitari'!$F$17*'Consumo e spesa'!F4)+('Consumo e spesa'!$O$23*('Ripart. u.i.'!O4/1000)) -> 139.95972
A9: Calcolo della spesa totale per unità | E9: St,1 | F9: =F7+F8 -> 768.00238 | G9: €
A11: Unità 2
A12: Calcolo della spesa per il consumo di energia termica utile per riscaldamento | E12: Sui,cli,2 | F12: ='Spese e costi unitari'!$F$16*'Consumo e spesa'!F6 -> 385.38155 | G12: €
A13: Calcolo della spesa per il consumo di energia termica utile per ACS | E13: Sui,acs,2 | F13: ='Spese e costi unitari'!$F$17*'Consumo e spesa'!F7 -> 50.628393 | G13: €
A14: Calcolo della spesa per potenza termica installata per Riscaldamento | E14: Sp,cli,2 | F14: ='Consumo e spesa'!$O$21*('Letture-mill. u.i.'!F47/1000) -> 292.68924 | G14: €
A15: Calcolo della spesa per potenza termica installata per ACS | E15: Sp,acs,2 | F15: ='Consumo e spesa'!$O$23*('Letture-mill. u.i.'!F48/1000) -> 50.399802 | G15: €
A16: Calcolo della spesa totale per Riscaldamento | E16: Scli,2 | F16: =F12+F14 -> 678.07079 | G16: €
A17: Calcolo della spesa totale per ACS | E17: Sacs,2 | F17: =F13+F15 -> 101.02819 | G17: €
A18: Calcolo della spesa totale per unità | E18: St,2 | F18: =F16+F17 -> 779.09899 | G18: €
A20: Unità 3
A21: Calcolo della spesa per il consumo di energia termica utile per riscaldamento | E21: Sui,cli,3 | F21: ='Spese e costi unitari'!$F$16*'Consumo e spesa'!F9 -> 137.40246 | G21: €
A22: Calcolo della spesa per il consumo di energia termica utile per ACS | E22: Sui,acs,3 | F22: ='Spese e costi unitari'!$F$17*'Consumo e spesa'!F10 -> 66.037034 | G22: €
A23: Calcolo della spesa per potenza termica installata per Riscaldamento | E23: Sp,cli,3 | F23: ='Consumo e spesa'!$O$21*('Letture-mill. u.i.'!F69/1000) -> 343.95814 | G23: €
A24: Calcolo della spesa per potenza termica installata per ACS | E24: Sp,acs,3 | F24: ='Consumo e spesa'!$O$23*('Letture-mill. u.i.'!F70/1000) -> 50.211392 | G24: €
A25: Calcolo della spesa totale per Riscaldamento | E25: Scli,3 | F25: =F21+F23 -> 481.36059 | G25: €
A26: Calcolo della spesa totale per ACS | E26: Sacs,3 | F26: =F22+F24 -> 116.24843 | G26: €
A27: Calcolo della spesa totale per unità | E27: St,3 | F27: =F25+F26 -> 597.60902 | G27: €
A29: Unità 4
A30: Calcolo della spesa per il consumo di energia termica utile per riscaldamento | E30: Sui,cli,4 | F30: ='Spese e costi unitari'!$F$16*'Consumo e spesa'!F12 -> 178.08029 | G30: €
A31: Calcolo della spesa per il consumo di energia termica utile per ACS | E31: Sui,acs,4 | F31: ='Spese e costi unitari'!$F$17*'Consumo e spesa'!F13 -> 125.47036 | G31: €
A32: Calcolo della spesa per potenza termica installata per Riscaldamento | E32: Sp,cli,4 | F32: ='Consumo e spesa'!$O$21*('Letture-mill. u.i.'!F95/1000) -> 324.82009 | G32: €
A33: Calcolo della spesa per potenza termica installata per ACS | E33: Sp,acs,4 | F33: ='Consumo e spesa'!$O$23*('Letture-mill. u.i.'!F96/1000) -> 50.329148 | G33: €
A34: Calcolo della spesa totale per Riscaldamento | E34: Scli,4 | F34: =F30+F32 -> 502.90038 | G34: €
A35: Calcolo della spesa totale per ACS | E35: Sacs,4 | F35: =F31+F33 -> 175.79951 | G35: €
A36: Calcolo della spesa totale per unità | E36: St,4 | F36: =F34+F35 -> 678.69989 | G36: €
A38: Unità 5
A39: Calcolo della spesa per il consumo di energia termica utile per riscaldamento | E39: Sui,cli,5 | F39: ='Spese e costi unitari'!$F$16*'Consumo e spesa'!F15 -> 263.38797 | G39: €
A40: Calcolo della spesa per il consumo di energia termica utile per ACS | E40: Sui,acs,5 | F40: ='Spese e costi unitari'!$F$17*'Consumo e spesa'!F16 -> 107.86049 | G40: €
A41: Calcolo della spesa per potenza termica installata per Riscaldamento | E41: Sp,cli,5 | F41: ='Consumo e spesa'!$O$21*('Letture-mill. u.i.'!F119/1000) -> 299.71237 | G41: €
A42: Calcolo della spesa per potenza termica installata per ACS | E42: Sp,acs,5 | F42: ='Consumo e spesa'!$O$23*('Letture-mill. u.i.'!F120/1000) -> 50.399802 | G42: €
A43: Calcolo della spesa totale per Riscaldamento | E43: Scli,5 | F43: =F39+F41 -> 563.10035 | G43: €
A44: Calcolo della spesa totale per ACS | E44: Sacs,5 | F44: =F40+F42 -> 158.26029 | G44: €
...

Sheet Foglio2
A2: Condomino | B2: Rilevatori | C2: Millesimi | D2: Millesimi ACS | E2: Consumi (kWh) | F2: Consumi ACS (kWh) | G2: Letture | H2: Letture ACS | I2: Totale Riscaldamento | J2: Totale ACS | K2: Totale
A3: alberizzi / piccirilli | B3: 7 | C3: 24.02 | D3: 25.78 | E3: ='Consumo e spesa'!F3 -> 1717.9043 | F3: ='Consumo e spesa'!F4 -> 1380.456 | G3: 5168 | H3: 36 | I3: =('Spese e costi unitari'!$F$16*'Consumo e spesa'!F3)+('Consumo e spesa'!$O$21*('Ripart. u.i.'!N4/1000)) -> 628.04266 | J3: =('Spese e costi unitari'!$F$17*'Consumo e spesa'!F4)+('Consumo e spesa'!$O$23*('Ripart. u.i.'!O4/1000)) -> 139.95972 | K3: =I3+J3 -> 768.00238
A4: ALBERIZZI/PISANI- Inq. APONE CLAUDIO | B4: 6 | C4: 16.67 | D4: 21.4 | E4: ='Consumo e spesa'!F6 -> 3209.1037 | F4: ='Consumo e spesa'!F7 -> 881.958 | G4: 9654 | H4: 23 | I4: =('Spese e costi unitari'!$F$16*'Consumo e spesa'!F6)+('Consumo e spesa'!$O$21*('Ripart. u.i.'!N5/1000)) -> 678.07079 | J4: =('Spese e costi unitari'!$F$17*'Consumo e spesa'!F7)+('Consumo e spesa'!$O$23*('Ripart. u.i.'!O5/1000)) -> 101.02819 | K4: =I4+J4 -> 779.09899
A5: APONE GIULIO | B5: 6 | C5: 19.59 | D5: 21.32 | E5: ='Consumo e spesa'!F9 -> 1144.1615 | F5: ='Consumo e spesa'!F10 -> 1150.38 | G5: 3442 | H5: 30 | I5: =('Spese e costi unitari'!$F$16*'Consumo e spesa'!F9)+('Consumo e spesa'!$O$21*('Ripart. u.i.'!N6/1000)) -> 481.36059 | J5: =('Spese e costi unitari'!$F$17*'Consumo e spesa'!F10)+('Consumo e spesa'!$O$23*('Ripart. u.i.'!O6/1000)) -> 116.24843 | K5: =I5+J5 -> 597.60902
A6: BADINI | B6: 6 | C6: 18.5 | D6: 21.37 | E6: ='Consumo e spesa'!F12 -> 1482.8891 | F6: ='Consumo e spesa'!F13 -> 2185.722 | G6: 4461 | H6: 57 | I6: =('Spese e costi unitari'!$F$16*'Consumo e spesa'!F12)+('Consumo e spesa'!$O$21*('Ripart. u.i.'!N7/1000)) -> 502.90038 | J6: =('Spese e costi unitari'!$F$17*'Consumo e spesa'!F13)+('Consumo e spesa'!$O$23*('Ripart. u.i.'!O7/1000)) -> 175.79951 | K6: =I6+J6 -> 678.69989
A7: BARBIERI | B7: 6 | C7: 17.07 | D7: 21.4 | E7: ='Consumo e spesa'!F15 -> 2193.2532 | F7: ='Consumo e spesa'!F16 -> 1878.954 | G7: 6598 | H7: 49 | I7: =('Spese e costi unitari'!$F$16*'Consumo e spesa'!F15)+('Consumo e spesa'!$O$21*('Ripart. u.i.'!N8/1000)) -> 563.10035 | J7: =('Spese e costi unitari'!$F$17*'Consumo e spesa'!F16)+('Consumo e spesa'!$O$23*('Ripart. u.i.'!O8/1000)) -> 158.26029 | K7: =I7+J7 -> 721.36064
A8: BATTISTOTTI / LANDI | B8: 7 | C8: 23.17 | D8: 25.87 | E8: ='Consumo e spesa'!F18 -> 1748.1538 | F8: ='Consumo e spesa'!F19 -> 1878.954 | G8: 5259 | H8: 49 | I8: =('Spese e costi unitari'!$F$16*'Consumo e spesa'!F18)+('Consumo e spesa'!$O$21*('Ripart. u.i.'!N9/1000)) -> 616.75116 | J8: =('Spese e costi unitari'!$F$17*'Consumo e spesa'!F19)+('Consumo e spesa'!$O$23*('Ripart. u.i.'!O9/1000)) -> 168.78773 | K8: =I8+J8 -> 785.53888
A9: BELLOMI viviana | B9: 5 | C9: 20.31 | D9: 2.06 | E9: ='Consumo e spesa'!F21 -> 345.7083 | F9: ='Consumo e spesa'!F22 -> 0 | G9: 1040 | H9: 0 | I9: =('Spese e costi unitari'!$F$16*'Consumo e spesa'!F21)+('Consumo e spesa'!$O$21*('Ripart. u.i.'!N10/1000)) -> 398.11592 | J9: =('Spese e costi unitari'!$F$17*'Consumo e spesa'!F22)+('Consumo e spesa'!$O$23*('Ripart. u.i.'!O10/1000)) -> 4.8515697 | K9: =I9+J9 -> 402.96749
A10: BERTUCCA IVAN | B10: 6 | C10: 16.8 | D10: 21.31 | E10: ='Consumo e spesa'!F24 -> 1024.8257 | F10: ='Consumo e spesa'!F25 -> 1572.186 | G10: 3083 | H10: 41 | I10: =('Spese e costi unitari'!$F$16*'Consumo e spesa'!F24)+('Consumo e spesa'!$O$21*('Ripart. u.i.'!N11/1000)) -> 418.04316 | J10: =('Spese e costi unitari'!$F$17*'Consumo e spesa'!F25)+('Consumo e spesa'!$O$23*('Ripart. u.i.'!O11/1000)) -> 140.43845 | K10: =I10+J10 -> 558.48161
A11: BLEJUT STEFAN | B11: 7 | C11: 28.87 | D11: 25.22 | E11: ='Consumo e spesa'!F27 -> 2272.6996 | F11: ='Consumo e spesa'!F28 -> 2147.376 | G11: 6837 | H11: 56 | I11: =('Spese e costi unitari'!$F$16*'Consumo e spesa'!F27)+('Consumo e spesa'!$O$21*('Ripart. u.i.'!N12/1000)) -> 779.82362 | J11: =('Spese e costi unitari'!$F$17*'Consumo e spesa'!F28)+('Consumo e spesa'!$O$23*('Ripart. u.i.'!O12/1000)) -> 182.66553 | K11: =I11+J11 -> 962.48915
A12: BOLLANI angelina | B12: 7 | C12: 20.38 | D12: 25.6 | E12: ='Consumo e spesa'!F30 -> 3867.2791 | F12: ='Consumo e spesa'!F31 -> 498.498 | G12: 11634 | H12: 13 | I12: =('Spese e costi unitari'!$F$16*'Consumo e spesa'!F30)+('Consumo e spesa'!$O$21*('Ripart. u.i.'!N13/1000)) -> 822.25073 | J12: =('Spese e costi unitari'!$F$17*'Consumo e spesa'!F31)+('Consumo e spesa'!$O$23*('Ripart. u.i.'!O13/1000)) -> 88.9074 | K12: =I12+J12 -> 911.15813
A13: CARENZIO - Inq.PAJERO | B13: 6 | C13: 16.96 | D13: 21.34 | E13: ='Consumo e spesa'!F33 -> 8952.1828 | F13: ='Consumo e spesa'!F34 -> 2837.604 | G13: 26931 | H13: 74 | I13: =('Spese e costi unitari'!$F$16*'Consumo e spesa'!F33)+('Consumo e spesa'!$O$21*('Ripart. u.i.'!N14/1000)) -> 1372.8494 | J13: =('Spese e costi unitari'!$F$17*'Consumo e spesa'!F34)+('Consumo e spesa'!$O$23*('Ripart. u.i.'!O14/1000)) -> 213.14984 | K13: =I13+J13 -> 1585.9993
A14: CASSE'' INQ. PEZZINI | B14: 7 | C14: 18.86 | D14: 25.83 | E14: ='Consumo e spesa'!F36 -> 1019.8395 | F14: ='Consumo e spesa'!F37 -> 1035.342 | G14: 3068 | H14: 27 | I14: =('Spese e costi unitari'!$F$16*'Consumo e spesa'!F36)+('Consumo e spesa'!$O$21*('Ripart. u.i.'!N15/1000)) -> 453.61353 | J14: =('Spese e costi unitari'!$F$17*'Consumo e spesa'!F37)+('Consumo e spesa'!$O$23*('Ripart. u.i.'!O15/1000)) -> 120.26636 | K14: =I14+J14 -> 573.87989
A15: CASSE natalia | B15: 6 | C15: 22.27 | D15: 21.31 | E15: ='Consumo e spesa'!F39 -> 718.67436 | F15: ='Consumo e spesa'!F40 -> 115.038 | G15: 2162 | H15: 3 | I15: =('Spese e costi unitari'!$F$16*'Consumo e spesa'!F39)+('Consumo e spesa'!$O$21*('Ripart. u.i.'!N16/1000)) -> 477.31882 | J15: =('Spese e costi unitari'!$F$17*'Consumo e spesa'!F40)+('Consumo e spesa'!$O$23*('Ripart. u.i.'!O16/1000)) -> 56.791544 | K15: =I15+J15 -> 534.11037
A16: CAVALLOTTI / rizzi | B16: 7 | C16: 20.97 | D16: 25.57 | E16: ='Consumo e spesa'!F42 -> 5664.9623 | F16: ='Consumo e spesa'!F43 -> 3681.216 | G16: 17042 | H16: 96 | I16: =('Spese e costi unitari'!$F$16*'Consumo e spesa'!F42)+('Consumo e spesa'!$O$21*('Ripart. u.i.'!N17/1000)) -> 1048.4938 | J16: =('Spese e costi unitari'!$F$17*'Consumo e spesa'!F43)+('Consumo e spesa'!$O$23*('Ripart. u.i.'!O17/1000)) -> 271.53921 | K16: =I16+J16 -> 1320.033
A17: CAYA | B17: 6 | C17: 21.4 | D17: 21.39 | E17: ='Consumo e spesa'!F45 -> 2304.2788 | F17: ='Consumo e spesa'!F46 -> 1840.608 | G17: 6932 | H17: 48 | I17: =('Spese e costi unitari'!$F$16*'Consumo e spesa'!F45)+('Consumo e spesa'!$O$21*('Ripart. u.i.'!N18/1000)) -> 652.45887 | J17: =('Spese e costi unitari'!$F$17*'Consumo e spesa'!F46)+('Consumo e spesa'!$O$23*('Ripart. u.i.'!O18/1000)) -> 156.03551 | K17: =I17+J17 -> 808.49438
A18: CEVARZERE | B18: 6 | C18: 18.46 | D18: 21.56 | E18: ='Consumo e spesa'!F48 -> 3993.5956 | F18: ='Consumo e spesa'!F49 -> 2607.528 | G18: 12014 | H18: 68 | I18: =('Spese e costi unitari'!$F$16*'Consumo e spesa'!F48)+('Consumo e spesa'!$O$21*('Ripart. u.i.'!N19/1000)) -> 803.70903 | J18: =('Spese e costi unitari'!$F$17*'Consumo e spesa'!F49)+('Consumo e spesa'!$O$23*('Ripart. u.i.'!O19/1000)) -> 200.46057 | K18: =I18+J18 -> 1004.1696
A19: civardi | B19: 7 | C19: 20.91 | D19: 25.25 | E19: ='Consumo e spesa'!F51 -> 352.02412 | F19: ='Consumo e spesa'!F52 -> 0 | G19: 1059 | H19: 0 | I19: =('Spese e costi unitari'!$F$16*'Consumo e spesa'!F51)+('Consumo e spesa'!$O$21*('Ripart. u.i.'!N20/1000)) -> 409.4091 | J19: =('Spese e costi unitari'!$F$17*'Consumo e spesa'!F52)+('Consumo e spesa'!$O$23*('Ripart. u.i.'!O20/1000)) -> 59.467056 | K19: =I19+J19 -> 468.87615
A20: CRISTIANI SERGIO Inq.MARZO | B20: 6 | C20: 21.21 | D20: 21.39 | E20: ='Consumo e spesa'!F54 -> 1026.8201 | F20: ='Consumo e spesa'!F55 -> 383.46 | G20: 3089 | H20: 10 | I20: =('Spese e costi unitari'!$F$16*'Consumo e spesa'!F54)+('Consumo e spesa'!$O$21*('Ripart. u.i.'!N21/1000)) -> 495.71276 | J20: =('Spese e costi unitari'!$F$17*'Consumo e spesa'!F55)+('Consumo e spesa'!$O$23*('Ripart. u.i.'!O21/1000)) -> 72.388595 | K20: =I20+J20 -> 568.10136
A21: D''ACUTO ANTONIO | B21: 7 | C21: 22.71 | D21: 25.26 | E21: ='Consumo e spesa'!F57 -> 2636.6906 | F21: ='Consumo e spesa'!F58 -> 2032.338 | G21: 7932 | H21: 53 | I21: =('Spese e costi unitari'!$F$16*'Consumo e spesa'!F57)+('Consumo e spesa'!$O$21*('Ripart. u.i.'!N22/1000)) -> 715.37901 | J21: =('Spese e costi unitari'!$F$17*'Consumo e spesa'!F58)+('Consumo e spesa'!$O$23*('Ripart. u.i.'!O22/1000)) -> 176.15603 | K21: =I21+J21 -> 891.53505
A22: DEL PRETE FRANCESCO | B22: 5 | C22: 21.2 | D22: 2.04 | E22: ='Consumo e spesa'!F60 -> 1735.8545 | F22: ='Consumo e spesa'!F61 -> 0 | G22: 5222 | H22: 0 | I22: =('Spese e costi unitari'!$F$16*'Consumo e spesa'!F60)+('Consumo e spesa'!$O$21*('Ripart. u.i.'!N23/1000)) -> 580.68519 | J22: =('Spese e costi unitari'!$F$17*'Consumo e spesa'!F61)+('Consumo e spesa'!$O$23*('Ripart. u.i.'!O23/1000)) -> 4.8044671 | K22: =I22+J22 -> 585.48966
A23: FERRARI | B23: 6 | C23: 17.26 | D23: 21.36 | E23: ='Consumo e spesa'!F63 -> 993.57894 | F23: ='Consumo e spesa'!F64 -> 38.346 | G23: 2989 | H23: 1 | I23: =('Spese e costi unitari'!$F$16*'Consumo e spesa'!F63)+('Consumo e spesa'!$O$21*('Ripart. u.i.'!N24/1000)) -> 422.36735 | J23: =('Spese e costi unitari'!$F$17*'Consumo e spesa'!F64)+('Consumo e spesa'!$O$23*('Ripart. u.i.'!O24/1000)) -> 52.506831 | K23: =I23+J23 -> 474.87418
A24: GALLI DONATELLA | B24: 5 | C24: 18.85 | D24: 21.56 | E24: ='Consumo e spesa'!F66 -> 750.91831 | F24: ='Consumo e spesa'!F67 -> 76.692 | G24: 2259 | H24: 2 | I24: =('Spese e costi unitari'!$F$16*'Consumo e spesa'!F66)+('Consumo e spesa'!$O$21*('Ripart. u.i.'!N25/1000)) -> 421.14318 | J24: =('Spese e costi unitari'!$F$17*'Consumo e spesa'!F67)+('Consumo e spesa'!$O$23*('Ripart. u.i.'!O25/1000)) -> 55.179092 | K24: =I24+J24 -> 476.32227
A25: MAGLIONA CATERINA | B25: 7 | C25: 19.04 | D25: 25.7 | E25: ='Consumo e spesa'!F69 -> 3103.0644 | F25: ='Consumo e spesa'!F70 -> 3681.216 | G25: 9335 | H25: 96 | I25: =('Spese e costi unitari'!$F$16*'Consumo e spesa'!F69)+('Consumo e spesa'!$O$21*('Ripart. u.i.'!N26/1000)) -> 706.9486 | J25: =('Spese e costi unitari'!$F$17*'Consumo e spesa'!F70)+('Consumo e spesa'!$O$23*('Ripart. u.i.'!O26/1000)) -> 271.84537 | K25: =I25+J25 -> 978.79397
A26: MARCONI anna | B26: 6 | C26: 18.04 | D26: 21.72 | E26: ='Consumo e spesa'!F72 -> 1873.1406 | F26: ='Consumo e spesa'!F73 -> 421.806 | G26: 5635 | H26: 11 | I26: =('Spese e costi unitari'!$F$16*'Consumo e spesa'!F72)+('Consumo e spesa'!$O$21*('Ripart. u.i.'!N27/1000)) -> 541.68911 | J26: =('Spese e costi unitari'!$F$17*'Consumo e spesa'!F73)+('Consumo e spesa'!$O$23*('Ripart. u.i.'!O27/1000)) -> 75.367023 | K26: =I26+J26 -> 617.05613
A27: MASCHERPA / fiorino - Inq.PROVELLI | B27: 6 | C27: 18.96 | D27: 21.45 | E27: ='Consumo e spesa'!F75 -> 6583.4162 | F27: ='Consumo e spesa'!F76 -> 2300.76 | G27: 19805 | H27: 60 | I27: =('Spese e costi unitari'!$F$16*'Consumo e spesa'!F75)+('Consumo e spesa'!$O$21*('Ripart. u.i.'!N28/1000)) -> 1123.4997 | J27: =('Spese e costi unitari'!$F$17*'Consumo e spesa'!F76)+('Consumo e spesa'!$O$23*('Ripart. u.i.'!O28/1000)) -> 182.59163 | K27: =I27+J27 -> 1306.0914
A28: MORISETTI | B28: 7 | C28: 19.43 | D28: 25.32 | E28: ='Consumo e spesa'!F78 -> 2711.4832 | F28: ='Consumo e spesa'!F79 -> 728.574 | G28: 8157 | H28: 19 | I28: =('Spese e costi unitari'!$F$16*'Consumo e spesa'!F78)+('Consumo e spesa'!$O$21*('Ripart. u.i.'!N29/1000)) -> 666.77115 | J28: =('Spese e costi unitari'!$F$17*'Consumo e spesa'!F79)+('Consumo e spesa'!$O$23*('Ripart. u.i.'!O29/1000)) -> 101.45537 | K28: =I28+J28 -> 768.22652
A29: naratone san pietro | B29: 6 | C29: 19.97 | D29: 21.56 | E29: ='Consumo e spesa'!F81 -> 2743.7272 | F29: ='Consumo e spesa'!F82 -> 345.114 | G29: 8254 | H29: 9 | I29: =('Spese e costi unitari'!$F$16*'Consumo e spesa'!F81)+('Consumo e spesa'!$O$21*('Ripart. u.i.'!N30/1000)) -> 680.12456 | J29: =('Spese e costi unitari'!$F$17*'Consumo e spesa'!F82)+('Consumo e spesa'!$O$23*('Ripart. u.i.'!O30/1000)) -> 70.587733 | K29: =I29+J29 -> 750.71229
A30: PAINELLI/CAPSONI | B30: 6 | C30: 16.62 | D30: 21.45 | E30: ='Consumo e spesa'!F84 -> 2302.2843 | F30: ='Consumo e spesa'!F85 -> 3067.68 | G30: 6926 | H30: 80 | I30: =('Spese e costi unitari'!$F$16*'Consumo e spesa'!F84)+('Consumo e spesa'!$O$21*('Ripart. u.i.'!N31/1000)) -> 568.29287 | J30: =('Spese e costi unitari'!$F$17*'Consumo e spesa'!F85)+('Consumo e spesa'!$O$23*('Ripart. u.i.'!O31/1000)) -> 226.61632 | K30: =I30+J30 -> 794.90919
A31: paladini | B31: 7 | C31: 23.22 | D31: 25.83 | E31: ='Consumo e spesa'!F87 -> 6318.1515 | F31: ='Consumo e spesa'!F88 -> 575.19 | G31: 19007 | H31: 15 | I31: =('Spese e costi unitari'!$F$16*'Consumo e spesa'!F87)+('Consumo e spesa'!$O$21*('Ripart. u.i.'!N32/1000)) -> 1166.4405 | J31: =('Spese e costi unitari'!$F$17*'Consumo e spesa'!F88)+('Consumo e spesa'!$O$23*('Ripart. u.i.'!O32/1000)) -> 93.851549 | K31: =I31+J31 -> 1260.292
A32: PANIGAZZI / lodola | B32: 7 | C32: 28.53 | D32: 23.43 | E32: ='Consumo e spesa'!F90 -> 1496.518 | F32: ='Consumo e spesa'!F91 -> 230.076 | G32: 4502 | H32: 6 | I32: =('Spese e costi unitari'!$F$16*'Consumo e spesa'!F90)+('Consumo e spesa'!$O$21*('Ripart. u.i.'!N33/1000)) -> 680.64223 | J32: =('Spese e costi unitari'!$F$17*'Consumo e spesa'!F91)+('Consumo e spesa'!$O$23*('Ripart. u.i.'!O33/1000)) -> 68.388125 | K32: =I32+J32 -> 749.03036
A33: PISOTTI | B33: 6 | C33: 23.86 | D33: 22.09 | E33: ='Consumo e spesa'!F93 -> 5587.1779 | F33: ='Consumo e spesa'!F94 -> 3911.292 | G33: 16808 | H33: 102 | I33: =('Spese e costi unitari'!$F$16*'Consumo e spesa'!F93)+('Consumo e spesa'!$O$21*('Ripart. u.i.'!N34/1000)) -> 1089.8948 | J33: =('Spese e costi unitari'!$F$17*'Consumo e spesa'!F94)+('Consumo e spesa'!$O$23*('Ripart. u.i.'!O34/1000)) -> 276.55076 | K33: =I33+J33 -> 1366.4456
A34: RIBONI | B34: 6 | C34: 23.15 | D34: 20.68 | E34: ='Consumo e spesa'!F96 -> 885.87751 | F34: ='Consumo e spesa'!F97 -> 0 | G34: 2665 | H34: 0 | I34: =('Spese e costi unitari'!$F$16*'Consumo e spesa'!F96)+('Consumo e spesa'!$O$21*('Ripart. u.i.'!N35/1000)) -> 512.84917 | J34: =('Spese e costi unitari'!$F$17*'Consumo e spesa'!F97)+('Consumo e spesa'!$O$23*('Ripart. u.i.'!O35/1000)) -> 48.704108 | K34: =I34+J34 -> 561.55327
A35: rossanigo inq. GUTIERREZ | B35: 7 | C35: 29.88 | D35: 25.16 | E35: ='Consumo e spesa'!F99 -> 5024.7371 | F35: ='Consumo e spesa'!F100 -> 4294.752 | G35: 15116 | H35: 112 | I35: =('Spese e costi unitari'!$F$16*'Consumo e spesa'!F99)+('Consumo e spesa'!$O$21*('Ripart. u.i.'!N36/1000)) -> 1128.0495 | J35: =('Spese e costi unitari'!$F$17*'Consumo e spesa'!F100)+('Consumo e spesa'!$O$23*('Ripart. u.i.'!O36/1000)) -> 305.79335 | K35: =I35+J35 -> 1433.8428
A36: ROVEDA / de santolo | B36: 6 | C36: 17.48 | D36: 21.63 | E36: ='Consumo e spesa'!F102 -> 4237.9183 | F36: ='Consumo e spesa'!F103 -> 2032.338 | G36: 12749 | H36: 53 | I36: =('Spese e costi unitari'!$F$16*'Consumo e spesa'!F102)+('Consumo e spesa'!$O$21*('Ripart. u.i.'!N37/1000)) -> 815.84308 | J36: =('Spese e costi unitari'!$F$17*'Consumo e spesa'!F103)+('Consumo e spesa'!$O$23*('Ripart. u.i.'!O37/1000)) -> 167.60691 | K36: =I36+J36 -> 983.44999
A37: SACCHI | B37: 7 | C37: 21.21 | D37: 25.29 | E37: ='Consumo e spesa'!F105 -> 5238.4779 | F37: ='Consumo e spesa'!F106 -> 805.266 | G37: 15759 | H37: 21 | I37: =('Spese e costi unitari'!$F$16*'Consumo e spesa'!F105)+('Consumo e spesa'!$O$21*('Ripart. u.i.'!N38/1000)) -> 1001.4911 | J37: =('Spese e costi unitari'!$F$17*'Consumo e spesa'!F106)+('Consumo e spesa'!$O$23*('Ripart. u.i.'!O38/1000)) -> 105.78719 | K37: =I37+J37 -> 1107.2783
A38: SALERNO | B38: 7 | C38: 18.83 | D38: 26.05 | E38: ='Consumo e spesa'!F108 -> 423.82507 | F38: ='Consumo e spesa'!F109 -> 1112.034 | G38: 1275 | H38: 29 | I38: =('Spese e costi unitari'!$F$16*'Consumo e spesa'!F108)+('Consumo e spesa'!$O$21*('Ripart. u.i.'!N39/1000)) -> 381.51137 | J38: =('Spese e costi unitari'!$F$17*'Consumo e spesa'!F109)+('Consumo e spesa'!$O$23*('Ripart. u.i.'!O39/1000)) -> 125.18696 | K38: =I38+J38 -> 506.69833
A39: SESTITO | B39: 7 | C39: 20.36 | D39: 25.29 | E39: ='Consumo e spesa'!F111 -> 2763.0071 | F39: ='Consumo e spesa'!F112 -> 1802.262 | G39: 8312 | H39: 47 | I39: =('Spese e costi unitari'!$F$16*'Consumo e spesa'!F111)+('Consumo e spesa'!$O$21*('Ripart. u.i.'!N40/1000)) -> 689.28744 | J39: =('Spese e costi unitari'!$F$17*'Consumo e spesa'!F112)+('Consumo e spesa'!$O$23*('Ripart. u.i.'!O40/1000)) -> 163.01928 | K39: =I39+J39 -> 852.30672
A40: SPAIRANI | B40: 5 | C40: 22.58 | D40: 21.21 | E40: ='Consumo e spesa'!F114 -> 1674.3584 | F40: ='Consumo e spesa'!F115 -> 1418.802 | G40: 5037 | H40: 37 | I40: =('Spese e costi unitari'!$F$16*'Consumo e spesa'!F114)+('Consumo e spesa'!$O$21*('Ripart. u.i.'!N41/1000)) -> 597.52993 | J40: =('Spese e costi unitari'!$F$17*'Consumo e spesa'!F115)+('Consumo e spesa'!$O$23*('Ripart. u.i.'!O41/1000)) -> 131.398 | K40: =I40+J40 -> 728.92793
A41: SUPER MARKET | B41: 1 | C41: 89.69 | D41: 11.14 | E41: ='Consumo e spesa'!F117 -> 0 | F41: ='Consumo e spesa'!F118 -> 0 | G41: 0 | H41: 0 | I41: =('Spese e costi unitari'!$F$16*'Consumo e spesa'!F117)+('Consumo e spesa'!$O$21*('Ripart. u.i.'!N42/1000)) -> 1574.7629 | J41: =('Spese e costi unitari'!$F$17*'Consumo e spesa'!F118)+('Consumo e spesa'!$O$23*('Ripart. u.i.'!O42/1000)) -> 26.236159 | K41: =I41+J41 -> 1600.9991
...
