Workbook

Sheet Dati generali
A2: Vettori energetici:
A3: Vettore 1 | I3: gas naturale
A4: Vettore 2 | I4: energia elettrica
A5: Generatori | I5: generatore a combustione per climatizzazione invernale e ACS
A6: Tipologia di contabilizzazione dell'energia termica utile prodotta dal generatore | I6: contatore di calore
A7: Numero di unità immobiliare | I7: 4
A8: Numero di locali ad uso collettivo | I8: 0
A9: Tipologia di contabilizzazione dei consumi di energia termica utile delle unità immobiliari per climatizzazione invernale | I9: ripartitori
A10: Tipologia di contabilizzazione dei consumi di energia termica utile delle unità immobiliari per ACS | I10: contatori volumetrici
A11: Periodo considerato | I11: stagione annuale
A12: Criterio di ripartizione della spesa totale per potenza termica installata per climatizzazione invernale | H12: Sp,cli | I12: millesimi di fabbisogno di energia termica utile
A13: Spesa totale per conduzione e manutenzione ordinaria dell'impianto centralizzato | H13: Scm | I13: 1892 | J13: €
A14: Spesa totale per la gestione del servizio di contabilizzazione dell'energia termica utile | H14: Scr | I14: 1376.16 | J14: €
A15: Perdite dell'impianto di climatizzazione invernale nel periodo considerato | H15: Pcli | I15: 90265 | J15: kWh
A16: Fabbisogno annuo di energia termica dell'edificio utile per climatizzazione invernale | H16: Qh,cli | I16: 336934 | J16: kWh
A17: Fabbisogno annuo di enrgia termica utile dell'edificio per ACS | H17: Qh,acs | I17: 53909 | J17: kWh

Sheet Vettori energetici
A1: Vettore 1 (combustibile)
A2: Lettura iniziale del contatore di combustibile | E2: L1,ct,1 | F2: 0 | G2: mc
A3: Lettura finale del contatore di combustibile | E3: L2,ct,1 | F3: 36124 | G3: mc
A4: Fabbisogno per climatizzazione invernale nel periodo considerato | E4: Q've,cli,1 | F4: =F3-F5 -> 30345 | G4: mc
A5: Fabbisogno per ACS nel periodo considerato | E5: Q've,acs,1 | F5: 5779 | G5: mc
A6: Costo unitario | E6: Cve,1 | F6: 0.9251 | G6: €/mc
A8: Vettore 2 (energia elettrica)
A9: Lettura iniziale del contatore di energia elettrica | E9: L1,ct,2 | F9: 0 | G9: kWh
A10: Lettura finale del contatore di energia elettrica | E10: L2,ct,2 | F10: 4465 | G10: kWh
A11: Fabbisogno per climatizzazione invernale nel periodo considerato | E11: Q've,cli,2 | F11: =F10-F12 -> 3751 | G11: kWh
A12: Fabbisogno per ACS nel periodo considerato | E12: Q've,acs,2 | F12: 714 | G12: kWh
A13: Costo unitario | E13: Cve,2 | F13: 0.3046 | G13: €/kWh

Sheet Generatore
A2: Generatore
A3: Lettura iniziale del contatore di calore | E3: L1,cc | F3: 0 | G3: kWh
A4: Lettura finale del contatore di calore | E4: L2,cc | F4: 336934 | G4: kWh
A5: Fabbisogno di energia termica utile applicato al generatore per climatizzazione invernale nel periodo considerato | E5: Q'gn,cli | F5: =F4-F6 -> 283025 | G5: kWh
A6: Fabbisogno di energia termica utile applicato al generatore per ACS nel periodo considerato | E6: Q'gn,acs | F6: 53909 | G6: kWh

Sheet Letture-mill. u.i.
A1: Unità immobiliare
A2: Unità immobiliare 1
A3: Lettura iniziale ripartitore - corpo scaldante 1 | E3: L1,r,1,1 | F3: 0 | G3: ur
A4: Lettura finale ripartitore - corpo scaldante 1 | E4: L2,r,1,1 | F4: 608 | G4: ur
A5: Lettura iniziale ripartitore - corpo scaldante 2 | E5: L1,r,2,1 | F5: 0 | G5: ur
A6: Lettura finale ripartitore - corpo scaldante 2 | E6: L2,r,2,1 | F6: 2016 | G6: ur
A7: Lettura iniziale ripartitore - corpo scaldante 3 | E7: L1,r,3,1 | F7: 0 | G7: ur
A8: Lettura finale ripartitore - corpo scaldante 3 | E8: L2,r,3,1 | F8: 1260 | G8: ur
A9: Lettura iniziale ripartitore - corpo scaldante 4 | E9: L1,r,4,1 | F9: 0 | G9: ur
A10: Lettura finale ripartitore - corpo scaldante 4 | E10: L2,r,4,1 | F10: 1512 | G10: ur
A11: Lettura iniziale ripartitore - corpo scaldante 5 | E11: L1,r,5,1 | F11: 0 | G11: ur
A12: Lettura finale ripartitore - corpo scaldante 5 | E12: L2,r,5,1 | F12: 1412 | G12: ur
A13: Lettura iniziale del contatore volumetrico | E13: L1,cv,1 | F13: 0 | G13: mc
A14: Lettura finale del contatore volumetrico | E14: L2,cv,1 | F14: 36 | G14: mc
A15: Millesimi di fabbisogno di energiatermica utile per climatizzazione invernale | E15: mQh,cli,1 | F15: 24.018
A16: Millesimi di fabbisogno di energiatermica utile per ACS | E16: mQh,acs,1 | F16: 25.766
A18: Unità immobiliare 2
A19: Lettura iniziale ripartitore - corpo scaldante 1 | E19: L1,r,1,2 | F19: 0 | G19: ur
A20: Lettura finale ripartitore - corpo scaldante 1 | E20: L2,r,1,2 | F20: 526 | G20: ur
A21: Lettura iniziale ripartitore - corpo scaldante 2 | E21: L1,r,2,2 | F21: 0 | G21: ur
A22: Lettura finale ripartitore - corpo scaldante 2 | E22: L2,r,2,2 | F22: 2248 | G22: ur
A23: Lettura iniziale ripartitore - corpo scaldante 3 | E23: L1,r,3,2 | F23: 0 | G23: ur
A24: Lettura finale ripartitore - corpo scaldante 3 | E24: L2,r,3,2 | F24: 1405 | G24: ur
A25: Lettura iniziale ripartitore - corpo scaldante 4 | E25: L1,r,4,2 | F25: 0 | G25: ur
A26: Lettura finale ripartitore - corpo scaldante 4 | E26: L2,r,4,2 | F26: 1706 | G26: ur
A27: Lettura iniziale ripartitore - corpo scaldante 5 | E27: L1,r,5,2 | F27: 0 | G27: ur
A28: Lettura finale ripartitore - corpo scaldante 5 | E28: L2,r,5,2 | F28: 1606 | G28: ur
A29: Lettura iniziale del contatore volumetrico | E29: L1,cv,2 | F29: 0 | G29: mc
A30: Lettura finale del contatore volumetrico | E30: L2,cv,2 | F30: 120 | G30: mc
A31: Millesimi di fabbisogno di energiatermica utile per climatizzazione invernale | E31: mQh,cli,2 | F31: 220
A32: Millesimi di fabbisogno di energiatermica utile per ACS | E32: mQh,acs,2
A34: Unità immobiliare 3
A35: Lettura iniziale ripartitore - corpo scaldante 1 | E35: L1,r,1,3 | F35: 0 | G35: ur
A36: Lettura finale ripartitore - corpo scaldante 1 | E36: L2,r,1,3 | F36: 608 | G36: ur
A37: Lettura iniziale ripartitore - corpo scaldante 2 | E37: L1,r,2,3 | F37: 0 | G37: ur
A38: Lettura finale ripartitore - corpo scaldante 2 | E38: L2,r,2,3 | F38: 2030 | G38: ur
A39: Lettura iniziale ripartitore - corpo scaldante 3 | E39: L1,r,3,3 | F39: 0 | G39: ur
A40: Lettura finale ripartitore - corpo scaldante 3 | E40: L2,r,3,3 | F40: 333 | G40: ur
A41: Lettura iniziale ripartitore - corpo scaldante 4 | E41: L1,r,4,3 | F41: 0 | G41: ur
A42: Lettura finale ripartitore - corpo scaldante 4 | E42: L2,r,4,3 | F42: 1923 | G42: ur
...

Sheet Consumi vet energ.
A2: Vettore 1 (combustibile)
A3: Calcolo del coefficiente di ripartizione per Riscaldamento | E3: kcli,1 | F3: ='Vettori energetici'!F4/('Vettori energetici'!F4+'Vettori energetici'!F5) -> 0.84002325
A4: Calcolo del coefficiente di ripartizione per ACS | E4: kacs,1 | F4: ='Vettori energetici'!F5/('Vettori energetici'!F4+'Vettori energetici'!F5) -> 0.15997675
A5: Calcolo del consumo per Riscaldamento | E5: Qve,cli,1 | F5: =('Vettori energetici'!F3-'Vettori energetici'!F2)*F3 -> 30345 | G5: mc
A6: Calcolo del consumo per ACS | E6: Qve,acs,1 | F6: =('Vettori energetici'!F3-'Vettori energetici'!F2)*F4 -> 5779 | G6: mc
A8: Vettore 2 (energia elettrica)
A9: Calcolo del coefficiente di ripartizione per Riscaldamento | E9: kcli,2 | F9: ='Vettori energetici'!F11/('Vettori energetici'!F11+'Vettori energetici'!F12) -> 0.84008959
A10: Calcolo del coefficiente di ripartizione per ACS | E10: kacs,2 | F10: ='Vettori energetici'!F12/('Vettori energetici'!F11+'Vettori energetici'!F12) -> 0.15991041
A11: Calcolo del consumo per Riscaldamento | E11: Qve,cli,2 | F11: =('Vettori energetici'!F10-'Vettori energetici'!F9)*F9 -> 3751 | G11: kWh
A12: Calcolo del consumo per ACS | E12: Qve,acs,2 | F12: =('Vettori energetici'!F10-'Vettori energetici'!F9)*F10 -> 714 | G12: kWh
A14: Calcolo dei contributi di energia termica utile del generatore
A15: Calcolo del coefficiente di ripartizione per Riscaldamento | E15: kcli | F15: =Generatore!F5/(Generatore!F5+Generatore!F6) -> 0.84000131
A16: Calcolo del coefficiente di ripartizione per ACS | E16: kacs | F16: =Generatore!F6/(Generatore!F5+Generatore!F6) -> 0.15999869
A17: Calcolo del contributo di energia termica utile per Riscaldamento | E17: Qgn,cli | F17: =(Generatore!F4-Generatore!F3)*F3 -> 283032.39 | G17: kWh
A18: Calcolo del contributo di energia termica utile per ACS | E18: Qgn,acs | F18: =(Generatore!F4-Generatore!F3)*F4 -> 53901.605 | G18: kWh
A20: Calcolo del consumo totale di energia termica utile dell'edificio per Riscaldamento e ACS
A21: Calcolo del consumo totale di energia termica utile dell'edificio per Riscaldamento | E21: Qcli | F21: =F17 -> 283032.39 | G21: kWh
A22: Calcolo del consumo totale di energia termica utile dell'edificio per ACS | E22: Qacs | F22: =F18 -> 53901.605 | G22: kWh
A23: Calcolo del consumo totale di energia termica utile dell'edificio per Riscaldamento e ACS | E23: Qt | F23: =F21+F22 -> 336934 | G23: kWh

Sheet Spese e costi unitari
A2: Calcolo della spesa totale per Riscaldamento e ACS
A3: Calcolo della spesa energetica per Riscaldamento | E3: Se,cli | F3: =('Vettori energetici'!F6*'Consumi vet energ.'!F5)+('Vettori energetici'!F13*'Consumi vet energ.'!F11) -> 29214.714 | G3: €
A4: Calcolo della spesa energetica per ACS | E4: Se,acs | F4: =('Vettori energetici'!F6*'Consumi vet energ.'!F6)+('Vettori energetici'!F13*'Consumi vet energ.'!F12) -> 5563.6373 | G4: €
A5: Calcolo del coefficiente di ripartizione per Riscaldamento | E5: kcli | F5: ='Dati generali'!I16/('Dati generali'!I16+'Dati generali'!I17) -> 0.86206994
A6: Calcolo del coefficiente di ripartizione per ACS | E6: kacs | F6: ='Dati generali'!I17/('Dati generali'!I16+'Dati generali'!I17) -> 0.13793006
A7: Calcolo della spesa per conduzione e manutenzione ordinaria dell'impianto termico centralizzato per Riscaldamento | E7: Scm,cli | F7: ='Dati generali'!I13*F5 -> 1631.0363 | G7: €
A8: Calcolo della spesa per conduzione e manutenzione ordinaria dell'impianto termico centralizzato per ACS | E8: Scm,acs | F8: ='Dati generali'!I13*F6 -> 260.96368 | G8: €
A9: Calcolo della spesa per la gestione del servizio di contabilizzazione dell'energia termica utile per Riscaldamento | E9: Scr,cli | F9: ='Dati generali'!I14*F5 -> 1186.3462 | G9: €
A10: Calcolo della spesa per la gestione del servizio di contabilizzazione dell'energia termica utile per ACS | E10: Scr,acs | F10: ='Dati generali'!I14*F6 -> 189.81384 | G10: €
A11: Calcolo della spesa totale per Riscaldamento | E11: Scli | F11: =F3+F7+F9 -> 32032.097 | G11: €
A12: Calcolo della spesa totale per ACS | E12: Sacs | F12: =F4+F8+F10 -> 6014.4148 | G12: €
A13: Calcolo della spesa totale per Riscaldamento e ACS | E13: St | F13: =F11+F12 -> 38046.511 | G13: €
A15: Calcolo dei costi unitari dell'energia termica utile
A16: Calcolo del costo unitario dell'energia termica utile per Riscaldamento | E16: ccli | F16: =F3/'Consumi vet energ.'!F21 -> 0.10322039 | G16: €/kWh
A17: Calcolo del costo unitario dell'energia termica utile per ACS | E17: cacs | F17: =F4/'Consumi vet energ.'!F22 -> 0.1032184 | G17: €/kWh
A19: Calcolo del consumo involontario di energia termica utile per Riscaldamento
A20: Calcolo del consumo involontario | E20: Qinv,cli | F20: ='Dati generali'!I15 -> 90265 | G20: kWh

Sheet Ripart. u.i.
A2: Calcolo delle unità di ripartizione delle singole unità immobiliari
A3: Unità immobiliare 1
A4: Calcolo delle unità di ripartizione del corpo scaldante 1 | E4: urcs,1,1 | F4: ='Letture-mill. u.i.'!F4-'Letture-mill. u.i.'!F3 -> 608 | G4: ur
A5: Calcolo delle unità di ripartizione del corpo scaldante 2 | E5: urcs,2,1 | F5: ='Letture-mill. u.i.'!F6-'Letture-mill. u.i.'!F5 -> 2016 | G5: ur
A6: Calcolo delle unità di ripartizione del corpo scaldante 3 | E6: urcs,3,1 | F6: ='Letture-mill. u.i.'!F8-'Letture-mill. u.i.'!F7 -> 1260 | G6: ur
A7: Calcolo delle unità di ripartizione del corpo scaldante 4 | E7: urcs,4,1 | F7: ='Letture-mill. u.i.'!F10-'Letture-mill. u.i.'!F9 -> 1512 | G7: ur
A8: Calcolo delle unità di ripartizione del corpo scaldante 5 | E8: urcs,5,1 | F8: ='Letture-mill. u.i.'!F12-'Letture-mill. u.i.'!F11 -> 1412 | G8: ur
A9: Calcolo delle unità di ripartizione del corpo scaldante i-esimo | E9: urcs,i,1 | G9: ur
A14: Calcolo delle unità di ripartizione dell'unità immobiliare | E14: ur1 | F14: 5168
A16: Unità immobiliare 2
A17: Calcolo delle unità di ripartizione del corpo scaldante 1 | E17: urcs,1,2 | F17: ='Letture-mill. u.i.'!F20-'Letture-mill. u.i.'!F19 -> 526 | G17: ur
A18: Calcolo delle unità di ripartizione del corpo scaldante 2 | E18: urcs,2,2 | F18: ='Letture-mill. u.i.'!F22-'Letture-mill. u.i.'!F21 -> 2248 | G18: ur
A19: Calcolo delle unità di ripartizione del corpo scaldante 3 | E19: urcs,3,2 | F19: ='Letture-mill. u.i.'!F24-'Letture-mill. u.i.'!F23 -> 1405 | G19: ur
A20: Calcolo delle unità di ripartizione del corpo scaldante 4 | E20: urcs,4,2 | F20: ='Letture-mill. u.i.'!F26-'Letture-mill. u.i.'!F25 -> 1706 | G20: ur
A21: Calcolo delle unità di ripartizione del corpo scaldante 5 | E21: urcs,5,2 | F21: ='Letture-mill. u.i.'!F28-'Letture-mill. u.i.'!F27 -> 1606 | G21: ur
A22: Calcolo delle unità di ripartizione del corpo scaldante i-esimo | E22: urcs,i,2 | G22: ur
A27: Calcolo delle unità di ripartizione dell'unità immobiliare | E27: ur2 | F27: =SUM(F17:F26) -> 7491
A29: Unità immobiliare 3
A30: Calcolo delle unità di ripartizione del corpo scaldante 1 | E30: urcs,1,3 | F30: ='Letture-mill. u.i.'!F36-'Letture-mill. u.i.'!F35 -> 608 | G30: ur
A31: Calcolo delle unità di ripartizione del corpo scaldante 2 | E31: urcs,2,3 | F31: ='Letture-mill. u.i.'!F38-'Letture-mill. u.i.'!F37 -> 2030 | G31: ur
A32: Calcolo delle unità di ripartizione del corpo scaldante 3 | E32: urcs,3,3 | F32: ='Letture-mill. u.i.'!F40-'Letture-mill. u.i.'!F39 -> 333 | G32: ur
A33: Calcolo delle unità di ripartizione del corpo scaldante 4 | E33: urcs,4,3 | F33: ='Letture-mill. u.i.'!F42-'Letture-mill. u.i.'!F41 -> 1923 | G33: ur
A34: Calcolo delle unità di ripartizione del corpo scaldante 5 | E34: urcs,5,3 | F34: ='Letture-mill. u.i.'!F44-'Letture-mill. u.i.'!F43 -> 1523 | G34: ur
A35: Calcolo delle unità di ripartizione del corpo scaldante i-esimo | E35: urcs,i,3 | G35: ur
A40: Calcolo delle unità di ripartizione dell'unità immobiliare | E40: ur3 | F40: =SUM(F30:F39) -> 6417
A42: Unità immobiliare 4
A43: Calcolo delle unità di ripartizione del corpo scaldante 1 | E43: urcs,1,4 | F43: ='Letture-mill. u.i.'!F52-'Letture-mill. u.i.'!F51 -> 496 | G43: ur
A44: Calcolo delle unità di ripartizione del corpo scaldante 2 | E44: urcs,2,4 | F44: ='Letture-mill. u.i.'!F54-'Letture-mill. u.i.'!F53 -> 1736 | G44: ur
A45: Calcolo delle unità di ripartizione del corpo scaldante 3 | E45: urcs,3,4 | F45: ='Letture-mill. u.i.'!F56-'Letture-mill. u.i.'!F55 -> 1016 | G45: ur
A46: Calcolo delle unità di ripartizione del corpo scaldante 4 | E46: urcs,4,4 | F46: ='Letture-mill. u.i.'!F58-'Letture-mill. u.i.'!F57 -> 1539 | G46: ur
A47: Calcolo delle unità di ripartizione del corpo scaldante 5 | E47: urcs,5,4 | F47: ='Letture-mill. u.i.'!F60-'Letture-mill. u.i.'!F59 -> 1239 | G47: ur
A48: Calcolo delle unità di ripartizione del corpo scaldante i-esimo | E48: urcs,i,4 | G48: ur
A53: Calcolo delle unità di ripartizione dell'unità immobiliare | E53: ur4 | F53: =SUM(F43:F52) -> 6026
A55: Unità immobiliare i-esima
A56: Calcolo delle unità di ripartizione del corpo scaldante 1 | E56: urcs,1,i | G56: ur
A57: Calcolo delle unità di ripartizione del corpo scaldante 2 | E57: urcs,2,i | G57: ur
A58: Calcolo delle unità di ripartizione del corpo scaldante 3 | E58: urcs,3,i | G58: ur
A59: Calcolo delle unità di ripartizione del corpo scaldante 4 | E59: urcs,4,i | G59: ur
A60: Calcolo delle unità di ripartizione del corpo scaldante 5 | E60: urcs,5,i | G60: ur
A61: Calcolo delle unità di ripartizione del corpo scaldante i-esimo | E61: urcs,i,i | G61: ur
...

Sheet Consumo e spesa
A1: Calcolo dei consumi di energia termica utile dellesingole unità immobiliari
A2: Unità 1 | J2: Calcolo delle componenti del consumo totale di energia termica utile dell'edificio per Riscaldamento e ACS
A3: Calcolo dei consumi di energia termica utile per Riscaldamento | E3: Qui,cli,1 | F3: =('Consumi vet energ.'!$F$21-'Spese e costi unitari'!$F$20)*('Ripart. u.i.'!F14/'Ripart. u.i.'!F75) -> 2726.835 | G3: kWh | J3: Calcolo delle componenti del consumo totale di energia termica utile dell'unità immobiliari per Riscaldamento | N3: Qui,cli,t | O3: =F3+F6+F9+F12+F15 -> 13244.778
A4: Calcolo dei consumi di energia termica utile per ACS | E4: Qui,acs,1 | F4: 1380.456 | O4: 194343.17 | P4: kWh
A5: Unità 2
A6: Calcolo dei consumi di energia termica utile per Riscaldamento | E6: Qui,cli,2 | F6: =('Consumi vet energ.'!$F$21-'Spese e costi unitari'!$F$20)*('Ripart. u.i.'!F27/'Ripart. u.i.'!$F$75) -> 3952.5389 | G6: kWh | J6: Calcolo delle componenti del consumo totale di energia termica utile dell'unità immobiliari per ACS | N6: Qui,acs,t
A7: Calcolo dei consumi di energia termica utile per ACS | E7: Qui,acs,2 | F7: 1 | O7: 63347.6 | P7: kWh
A8: Unità 3 | O8: 2
A9: Calcolo dei consumi di energia termica utile per Riscaldamento | E9: Qui,cli,3 | F9: =('Consumi vet energ.'!$F$21-'Spese e costi unitari'!$F$20)*('Ripart. u.i.'!F40/'Ripart. u.i.'!$F$75) -> 3385.8553 | G9: kWh | J9: Calcolo del consumo involontario di energia termica utile per ACS | N9: Qinv,acs
A10: Calcolo dei consumi di energia termica utile per ACS | E10: Qui,acs,3 | F10: 1 | O10: ='Consumi vet energ.'!F22-O7 -> -9445.9948 | P10: kWh
A11: Unità 4
A12: Calcolo dei consumi di energia termica utile per Riscaldamento | E12: Qui,cli,4 | F12: =('Consumi vet energ.'!$F$21-'Spese e costi unitari'!$F$20)*('Ripart. u.i.'!F53/'Ripart. u.i.'!$F$75) -> 3179.5487 | G12: kWh
A13: Calcolo dei consumi di energia termica utile per ACS | E13: Qui,acs,4 | F13: 1 | J13: Calcolo delle componenti della spesa totale per Riscaldamento e ACS
A14: Unità i-esima | J14: Calcolo delle componenti della spesa totale per il consumo di energia termica utile delle unità immobiliari per Riscaldamento | N14: Sui,cli
A15: Calcolo dei consumi di energia termica utile per Riscaldamento | E15: Qui,cli,i | G15: kWh | O15: ='Spese e costi unitari'!F16*O4 -> 20060.178 | P15: €
A16: Calcolo dei consumi di energia termica utile per ACS | E16: Qui,acs,1 | F16: 1
J17: Calcolo delle componenti della spesa totale per il consumo di energia termica utile delle unità immobiliari per ACS | N17: Sui,acs
O18: ='Spese e costi unitari'!F17*O7 -> 6538.6377 | P18: €
J20: Calcolo della spesa totale per potenza termica installata per Riscaldamento | N20: Sp,cli
O21: =('Spese e costi unitari'!F16*'Spese e costi unitari'!F20)+'Spese e costi unitari'!F7+'Spese e costi unitari'!F9 -> 12134.571 | P21: €
J22: Calcolo della spesa totale per potenza termica installata per ACS | N22: Sp,acs
O23: =('Spese e costi unitari'!F17*O10)+'Spese e costi unitari'!F8+'Spese e costi unitari'!F10 -> -524.22293 | P23: €
A29: 1 | B29: Qui,acs,1= (L2,cv - L1,cv) x mv x qp x (θacs - θf) [kWh]
B31: dove
B32: L1,cv | C32: lettura iniziale contatore volumetrico (m3) | L32: =36*1.162*0.001*1000*33 -> 1380.456
B33: L2,cv | C33: lettura finale contatore volumetrico (m3)
B34: mv | C34: massa volumica acqua (1000 kg/m3)
B35: qp | C35: calore specifico acqua a pressione costante (1,162 x 10-3 Wh/kg x °C)
B36: θacs | C36: temperatura media acqua ACS nel pun to di misura del volume prelevato (tipicamente 48°C)
B37: θf | C37: temperatura media dell'acqua fredda (15°C)
B39: esempio Unità 1
B40: Qui,acs,1= (100 - 0) x1,162 x 10-3 x 1000 x (48-15) = 3834,6 kWh
A44: 2 | B44: Qui,acs,t = Qui,acs,1 + Qui,acs,2 + Qui,acs,3 + Qui,acs,4 + Qui,acs,i-esima

Sheet Spese u.i.
A1: Calcolo delle spese delle singole unità immobiliari
A2: Unità 1
A3: Calcolo della spesa per il consumo di energia termica utile per riscaldamento | E3: Sui,cli,1 | F3: ='Spese e costi unitari'!$F$16*'Consumo e spesa'!F3 -> 281.46497 | G3: €
A4: Calcolo della spesa per il consumo di energia termica utile per ACS | E4: Sui,acs,1 | F4: ='Spese e costi unitari'!$F$17*'Consumo e spesa'!F4 -> 142.48846 | G4: €
A5: Calcolo della spesa per potenza termica installata per Riscaldamento | E5: Sp,cli,1 | F5: ='Consumo e spesa'!$O$21*('Letture-mill. u.i.'!F15/1000) -> 291.44813 | G5: €
A6: Calcolo della spesa per potenza termica installata per ACS | E6: Sp,acs,1 | F6: ='Consumo e spesa'!$O$23*('Letture-mill. u.i.'!F16/1000) -> -13.507128 | G6: €
A7: Calcolo della spesa totale per Riscaldamento | E7: Scli,1 | F7: =F3+F5 -> 572.9131 | G7: €
A8: Calcolo della spesa totale per ACS | E8: Sacs,1 | F8: =F4+F6 -> 128.98133 | G8: €
A9: Calcolo della spesa totale per unità | E9: St,1 | F9: =F7+F8 -> 701.89442 | G9: €
A11: Unità 1
A12: Calcolo della spesa per il consumo di energia termica utile per riscaldamento | E12: Sui,cli,1 | F12: ='Spese e costi unitari'!$F$16*'Consumo e spesa'!F6 -> 407.9826 | G12: €
A13: Calcolo della spesa per il consumo di energia termica utile per ACS | E13: Sui,acs,1 | F13: ='Spese e costi unitari'!$F$17*'Consumo e spesa'!F7 -> 0.1032184 | G13: €
A14: Calcolo della spesa per potenza termica installata per Riscaldamento | E14: Sp,cli,1 | F14: ='Consumo e spesa'!$O$21*('Letture-mill. u.i.'!F31/1000) -> 2669.6056 | G14: €
A15: Calcolo della spesa per potenza termica installata per ACS | E15: Sp,acs,1 | F15: ='Consumo e spesa'!$O$23*('Letture-mill. u.i.'!F32/1000) -> 0 | G15: €
A16: Calcolo della spesa totale per Riscaldamento | E16: Scli,1 | F16: =F12+F14 -> 3077.5882 | G16: €
A17: Calcolo della spesa totale per ACS | E17: Sacs,1 | F17: =F13+F15 -> 0.1032184 | G17: €
A18: Calcolo della spesa totale per unità | E18: St,1 | F18: =F16+F17 -> 3077.6914 | G18: €
A20: Unità 1
A21: Calcolo della spesa per il consumo di energia termica utile per riscaldamento | E21: Sui,cli,1 | F21: ='Spese e costi unitari'!$F$16*'Consumo e spesa'!F9 -> 349.4893 | G21: €
A22: Calcolo della spesa per il consumo di energia termica utile per ACS | E22: Sui,acs,1 | F22: ='Spese e costi unitari'!$F$17*'Consumo e spesa'!F10 -> 0.1032184 | G22: €
A23: Calcolo della spesa per potenza termica installata per Riscaldamento | E23: Sp,cli,1 | F23: ='Consumo e spesa'!$O$21*('Letture-mill. u.i.'!F47/1000) -> 3397.6799 | G23: €
A24: Calcolo della spesa per potenza termica installata per ACS | E24: Sp,acs,1 | F24: ='Consumo e spesa'!$O$23*('Letture-mill. u.i.'!F48/1000) -> 0 | G24: €
A25: Calcolo della spesa totale per Riscaldamento | E25: Scli,1 | F25: =F21+F23 -> 3747.1692 | G25: €
A26: Calcolo della spesa totale per ACS | E26: Sacs,1 | F26: =F22+F24 -> 0.1032184 | G26: €
A27: Calcolo della spesa totale per unità | E27: St,1 | F27: =F25+F26 -> 3747.2724 | G27: €
A29: Unità 1
A30: Calcolo della spesa per il consumo di energia termica utile per riscaldamento | E30: Sui,cli,1 | F30: ='Spese e costi unitari'!$F$16*'Consumo e spesa'!F12 -> 328.19426 | G30: €
A31: Calcolo della spesa per il consumo di energia termica utile per ACS | E31: Sui,acs,1 | F31: ='Spese e costi unitari'!$F$17*'Consumo e spesa'!F13 -> 0.1032184 | G31: €
A32: Calcolo della spesa per potenza termica installata per Riscaldamento | E32: Sp,cli,1 | F32: ='Consumo e spesa'!$O$21*('Letture-mill. u.i.'!F63/1000) -> 3397.6799 | G32: €
A33: Calcolo della spesa per potenza termica installata per ACS | E33: Sp,acs,1 | F33: ='Consumo e spesa'!$O$23*('Letture-mill. u.i.'!F64/1000) -> 0 | G33: €
A34: Calcolo della spesa totale per Riscaldamento | E34: Scli,1 | F34: =F30+F32 -> 3725.8741 | G34: €
A35: Calcolo della spesa totale per ACS | E35: Sacs,1 | F35: =F31+F33 -> 0.1032184 | G35: €
A36: Calcolo della spesa totale per unità | E36: St,1 | F36: =F34+F35 -> 3725.9773 | G36: €

Sheet Dati condominio
A1: lettura acs | B1: consumi energia termica acs | D1: lettura HCA | E1: consumi energia termica HCA
A2: 36 | B2: =A2*0.001162*1000*33 -> 1380.456 | D2: 5168 | E2: 2749.12
A3: 23 | B3: =A3*0.001162*1000*33 -> 881.958 | D3: 9654 | E3: 5135.46
A4: 30 | B4: =A4*0.001162*1000*33 -> 1150.38 | D4: 3442 | E4: 1830.98
A5: 57 | B5: =A5*0.001162*1000*33 -> 2185.722 | D5: 4461 | E5: 2373.04
A6: 49 | B6: =A6*0.001162*1000*33 -> 1878.954 | D6: 6598 | E6: 3509.82
A7: 49 | B7: =A7*0.001162*1000*33 -> 1878.954 | D7: 5259 | E7: 2797.53
A8: 0 | B8: =A8*0.001162*1000*33 -> 0 | D8: 1040 | E8: 553.23
A9: 41 | B9: =A9*0.001162*1000*33 -> 1572.186 | D9: 3083 | E9: 1640.01
A10: 56 | B10: =A10*0.001162*1000*33 -> 2147.376 | D10: 6837 | E10: 3636.95
A11: 13 | B11: =A11*0.001162*1000*33 -> 498.498 | D11: 11634 | E11: 6188.72
A12: 74 | B12: =A12*0.001162*1000*33 -> 2837.604 | D12: 26931 | E12: 14325.98
A13: 27 | B13: =A13*0.001162*1000*33 -> 1035.342 | D13: 3068 | E13: 1632.03
... A46: 28 | B46: =A46*0.001162*1000*33 -> 1073.688 | D46: 11593 | E46: 6166.91
A48: =SUM(A2:A47) -> 1652 | B48: =SUM(B2:B47) -> 63347.592 | D48: =SUM(D2:D47) -> 365340 | E48: =SUM(E2:E47) -> 194343.17

Sheet Risultato
A1: COSTI PER UNITA' espressi in € - VALORI DAL 01/01/2017 AL 31/12/2017
A2: Denominazione | B2: Ripartitori installati | C2: Lettura HCA | D2: Calcolo della spesa per il consumo di energia termica utile per riscaldamento | E2: Calcolo della spesa per il consumo di energia termica utile per ACS | F2: Calcolo della spesa per potenza termica installata per Riscaldamento | G2: Calcolo della spesa per potenza termica installata per ACS | H2: Calcolo della spesa totale per Riscaldamento | I2: Calcolo della spesa totale per ACS | J2: Calcolo della spesa totale per unità
A3: ALBERIZZI / PICCIRILLI | B3: 7 | C3: 5168 | D3: 284.98 | E3: 143.29 | F3: 292.43 | G3: -17.87 | H3: 577.41 | I3: 125.42 | J3: 702.83
A4: ALBERIZZI/PISANI- INQ. APONE CLAUDIO | B4: 6 | C4: 9654 | D4: 532.36 | E4: 91.55 | F4: 202.95 | G4: -14.84 | H4: 735.3 | I4: 76.71 | J4: 812.01
A5: APONE GIULIO | B5: 6 | C5: 3442 | D5: 189.8 | E5: 119.41 | F5: 238.5 | G5: -14.78 | H5: 428.3 | I5: 104.63 | J5: 532.93
A6: BADINI | B6: 6 | C6: 4461 | D6: 246 | E6: 226.88 | F6: 225.23 | G6: -14.82 | H6: 471.22 | I6: 212.06 | J6: 683.28
A7: BARBIERI | B7: 6 | C7: 6598 | D7: 363.84 | E7: 195.04 | F7: 207.82 | G7: -14.84 | H7: 571.66 | I7: 180.2 | J7: 751.86
A8: BATTISTOTTI / LANDI | B8: 7 | C8: 5259 | D8: 290 | E8: 195.04 | F8: 282.08 | G8: -17.94 | H8: 572.08 | I8: 177.1 | J8: 749.18
A9: BELLOMI VIVIANA | B9: 5 | C9: 1040 | D9: 57.35 | E9: 0 | F9: 247.26 | G9: -1.43 | H9: 304.61 | I9: -1.43 | J9: 303.18
A10: BERTUCCA IVAN | B10: 6 | C10: 3083 | D10: 170.01 | E10: 163.2 | F10: 204.53 | G10: -14.77 | H10: 374.54 | I10: 148.43 | J10: 522.97
A11: BLEJUT STEFAN | B11: 7 | C11: 6837 | D11: 377.02 | E11: 222.9 | F11: 351.48 | G11: -17.49 | H11: 728.49 | I11: 205.41 | J11: 933.9
A12: BOLLANI ANGELINA | B12: 7 | C12: 11634 | D12: 641.54 | E12: 51.75 | F12: 248.12 | G12: -17.75 | H12: 889.66 | I12: 34 | J12: 923.66
A13: CARENZIO - INQ.PAJERO | B13: 6 | C13: 26931 | D13: 1485.07 | E13: 294.55 | F13: 206.48 | G13: -14.8 | H13: 1691.55 | I13: 279.75 | J13: 1971.3
A14: CASSE' INQ. PEZZINI | B14: 7 | C14: 3068 | D14: 169.18 | E14: 107.47 | F14: 229.61 | G14: -17.91 | H14: 398.79 | I14: 89.56 | J14: 488.35
... A47: ZOCCALI FABIO | B47: 7 | C47: 11593 | D47: 639.28 | E47: 111.45 | F47: 234.6 | G47: -17.91 | H47: 873.88 | I47: 93.54 | J47: 967.42
A48: TOTALE | B48: 282 | C48: 365340 | D48: 20146.16 | E48: 6575.61 | F48: 11596.07 | G48: -.676,60 | H48: 31742.25 | I48: 5899.01 | J48: 37641.26

Sheet Foglio1
A3: scheda9formula4 | C3: = | D3: scheda8formula9*(scheda4F16/1000) | I3: 6605*(25,766/1000)
D4: =6605*(25.766/1000) -> 170.18443
B6: scheda4F16 | D6: = | E6: millesimi ACS | I6: 25.766
B8: scheda8formula9 | D8: = | E8: (scheda6formua13*scheda8formula5)+(scheda6formula6+scheda6formula8) | N8: (0,1*62032)+(200,25+182,07)
E9: =(0.1*62032)+(200.25+182.07) -> 6585.52
C11: scheda6formula13 | E11: = | F11: scheda6formula2/scheda5formula10 | L11: 7779,71/77754
F12: =7779.71/77754 -> 0.10005543
C14: scheda8formula5 | E14: = | F14: scheda5formula10-scheda8formula4 | N14: 36124*0,11 | P14: =36124*0.11 -> 3973.64
C17: scheda6fomrula6 | E17: = | F17: scheda1I13*scheda6formula4 | K17: 1892*0,11
F18: =1892*0.11 -> 208.12
C20: scheda6formula8 | E20: = | F20: scehda1I14*scheda6formula4 | K20: 1720,20*0,11
F21: =1720.2*0.11 -> 189.222
